{
  "version": 8,
  "blockIdVersion": 11,
  "anchorX": 0,
  "anchorY": 0,
  "anchorZ": 0,
  "blocks": [
    {
      "x": -3,
      "y": 0,
      "z": -3,
      "name": "Rock_Slate_Cobble"
    },
    {
      "x": -3,
      "y": 1,
      "z": -3,
      "name": "Rock_Slate_Cobble"
    },
    {
      "x": -3,
      "y": 2,
      "z": -3,
      "name": "Rock_Slate_Cobble"
    },
    {
      "x": -3,
      "y": 3,
      "z": -3,
      "name": "Rock_Slate_Cobble"
    },
    {
      "x": -3,
      "y": 4,
      "z": -3,
      "name": "Rock_Slate_Cobble"
    },
    {
      "x": -3,
      "y": 5,
      "z": -3,
      "name": "Rock_Slate_Cobble"
    },
    {
      "x": -3,
      "y": 6,
      "z": -3,
      "name": "Rock_Slate_Cobble"
    },
    {
      "x": -3,
      "y": 3,
      "z": -2,
      "name": "Ore_Server"
    },
    {
      "x": -3,
      "y": 5,
      "z": -2,
      "name": "Deco_SpiderWeb",
      "support": 15,
      "rotation": 11
    },
    {
      "x": -3,
      "y": 6,
      "z": -2,
      "name": "Rock_Slate_Cobble"
    },
    {
      "x": -3,
      "y": 6,
      "z": -1,
      "name": "Rock_Slate_Cobble"
    },
    {
      "x": -3,
      "y": 5,
      "z": 0,
      "name": "Deco_SpiderWeb",
      "support": 15,
      "rotation": 9
    },
    {
      "x": -3,
      "y": 6,
      "z": 0,
      "name": "Rock_Slate_Cobble"
    },
    {
      "x": -3,
      "y": 0,
      "z": 1,
      "name": "Rock_Slate_Cobble"
    },
    {
      "x": -3,
      "y": 1,
      "z": 1,
      "name": "Rock_Slate_Cobble"
    },
    {
      "x": -3,
      "y": 2,
      "z": 1,
      "name": "Rock_Slate_Cobble"
    },
    {
      "x": -3,
      "y": 3,
      "z": 1,
      "name": "Rock_Slate_Cobble"
    },
    {
      "x": -3,
      "y": 4,
      "z": 1,
      "name": "Rock_Slate_Cobble"
    },
    {
      "x": -3,
      "y": 5,
      "z": 1,
      "name": "Rock_Slate_Cobble"
    },
    {
      "x": -3,
      "y": 6,
      "z": 1,
      "name": "Rock_Slate_Cobble"
    },
    {
      "x": -3,
      "y": 7,
      "z": 1,
      "name": "Rock_Slate_Cobble"
    },
    {
      "x": -3,
      "y": 4,
      "z": 2,
      "name": "Rock_Slate_Cobble"
    },
    {
      "x": -3,
      "y": 3,
      "z": 3,
      "name": "Deco_SpiderWeb",
      "support": 15,
      "rotation": 9
    },
    {
      "x": -3,
      "y": 4,
      "z": 3,
      "name": "Rock_Slate_Cobble"
    },
    {
      "x": -3,
      "y": 0,
      "z": 4,
      "name": "Rock_Slate_Cobble"
    },
    {
      "x": -3,
      "y": 1,
      "z": 4,
      "name": "Rock_Slate_Cobble"
    },
    {
      "x": -3,
      "y": 2,
      "z": 4,
      "name": "Rock_Slate_Cobble"
    },
    {
      "x": -3,
      "y": 3,
      "z": 4,
      "name": "Rock_Slate_Cobble"
    },
    {
      "x": -3,
      "y": 4,
      "z": 4,
      "name": "Rock_Slate_Cobble"
    },
    {
      "x": -2,
      "y": 3,
      "z": -3,
      "name": "Rock_Slate_Cobble"
    },
    {
      "x": -2,
      "y": 2,
      "z": 1,
      "name": "Rock_Slate_Cobble"
    },
    {
      "x": -2,
      "y": 2,
      "z": 3,
      "name": "Ore_Server"
    },
    {
      "x": -2,
      "y": 2,
      "z": 4,
      "name": "Rock_Slate_Cobble"
    },
    {
      "x": -1,
      "y": 3,
      "z": -3,
      "name": "Rock_Slate_Cobble"
    },
    {
      "x": -1,
      "y": 4,
      "z": 1,
      "name": "Ore_Server"
    },
    {
      "x": -1,
      "y": 2,
      "z": 4,
      "name": "Rock_Slate_Cobble"
    },
    {
      "x": 0,
      "y": 0,
      "z": -3,
      "name": "Rock_Slate_Cobble"
    },
    {
      "x": 0,
      "y": 1,
      "z": -3,
      "name": "Rock_Slate_Cobble"
    },
    {
      "x": 0,
      "y": 2,
      "z": -3,
      "name": "Rock_Slate_Cobble"
    },
    {
      "x": 0,
      "y": 3,
      "z": -3,
      "name": "Rock_Slate_Cobble"
    },
    {
      "x": 0,
      "y": 4,
      "z": -3,
      "name": "Rock_Slate_Cobble"
    },
    {
      "x": 0,
      "y": 5,
      "z": -3,
      "name": "Rock_Slate_Cobble"
    },
    {
      "x": 0,
      "y": 3,
      "z": -2,
      "name": "Deco_SpiderWeb_Full",
      "support": 15
    },
    {
      "x": 0,
      "y": 4,
      "z": -2,
      "name": "Rock_Slate_Cobble"
    },
    {
      "x": 0,
      "y": 4,
      "z": -1,
      "name": "Rock_Slate_Cobble"
    },
    {
      "x": 0,
      "y": 4,
      "z": 0,
      "name": "Rock_Slate_Cobble"
    },
    {
      "x": 0,
      "y": 4,
      "z": 1,
      "name": "Rock_Slate_Cobble"
    },
    {
      "x": 0,
      "y": 4,
      "z": 2,
      "name": "Rock_Slate_Cobble"
    },
    {
      "x": 0,
      "y": 3,
      "z": 3,
      "name": "Deco_SpiderWeb",
      "support": 15,
      "rotation": 8
    },
    {
      "x": 0,
      "y": 4,
      "z": 3,
      "name": "Rock_Slate_Cobble"
    },
    {
      "x": 0,
      "y": 2,
      "z": 4,
      "name": "Rock_Slate_Cobble"
    },
    {
      "x": 0,
      "y": 3,
      "z": 4,
      "name": "Rock_Slate_Cobble"
    },
    {
      "x": 0,
      "y": 4,
      "z": 4,
      "name": "Rock_Slate_Cobble"
    },
    {
      "x": 1,
      "y": 1,
      "z": -3,
      "name": "Rock_Slate_Cobble"
    },
    {
      "x": 1,
      "y": 4,
      "z": -3,
      "name": "Rock_Slate_Cobble"
    },
    {
      "x": 1,
      "y": 3,
      "z": 1,
      "name": "Deco_SpiderWeb",
      "support": 15,
      "rotation": 8
    },
    {
      "x": 1,
      "y": 4,
      "z": 1,
      "name": "Rock_Slate_Cobble"
    },
    {
      "x": 1,
      "y": 2,
      "z": 4,
      "name": "Rock_Slate_Cobble"
    },
    {
      "x": 2,
      "y": 0,
      "z": -3,
      "name": "Rock_Slate_Cobble"
    },
    {
      "x": 2,
      "y": 1,
      "z": -3,
      "name": "Rock_Slate_Cobble"
    },
    {
      "x": 2,
      "y": 4,
      "z": -3,
      "name": "Rock_Slate_Cobble"
    },
    {
      "x": 2,
      "y": 0,
      "z": 1,
      "name": "Rock_Slate_Cobble"
    },
    {
      "x": 2,
      "y": 1,
      "z": 1,
      "name": "Rock_Slate_Cobble"
    },
    {
      "x": 2,
      "y": 2,
      "z": 1,
      "name": "Rock_Slate_Cobble"
    },
    {
      "x": 2,
      "y": 3,
      "z": 1,
      "name": "Rock_Slate_Cobble"
    },
    {
      "x": 2,
      "y": 4,
      "z": 1,
      "name": "Rock_Slate_Cobble"
    },
    {
      "x": 2,
      "y": 0,
      "z": 2,
      "name": "Ore_Server"
    },
    {
      "x": 2,
      "y": 1,
      "z": 2,
      "name": "Deco_SpiderWeb",
      "support": 15,
      "rotation": 9
    },
    {
      "x": 2,
      "y": 2,
      "z": 4,
      "name": "Rock_Slate_Cobble"
    },
    {
      "x": 3,
      "y": 1,
      "z": -3,
      "name": "Rock_Slate_Cobble"
    },
    {
      "x": 3,
      "y": 4,
      "z": -3,
      "name": "Rock_Slate_Cobble"
    },
    {
      "x": 3,
      "y": 1,
      "z": 0,
      "name": "Ore_Server"
    },
    {
      "x": 3,
      "y": 1,
      "z": 1,
      "name": "Rock_Slate_Cobble"
    },
    {
      "x": 3,
      "y": 0,
      "z": 4,
      "name": "Rock_Slate_Cobble"
    },
    {
      "x": 3,
      "y": 1,
      "z": 4,
      "name": "Rock_Slate_Cobble"
    },
    {
      "x": 3,
      "y": 2,
      "z": 4,
      "name": "Rock_Slate_Cobble"
    },
    {
      "x": 4,
      "y": 0,
      "z": -3,
      "name": "Rock_Slate_Cobble"
    },
    {
      "x": 4,
      "y": 1,
      "z": -3,
      "name": "Rock_Slate_Cobble"
    },
    {
      "x": 4,
      "y": 2,
      "z": -3,
      "name": "Rock_Slate_Cobble"
    },
    {
      "x": 4,
      "y": 3,
      "z": -3,
      "name": "Rock_Slate_Cobble"
    },
    {
      "x": 4,
      "y": 4,
      "z": -3,
      "name": "Rock_Slate_Cobble"
    },
    {
      "x": 4,
      "y": 5,
      "z": -3,
      "name": "Rock_Slate_Cobble"
    },
    {
      "x": 4,
      "y": 1,
      "z": -2,
      "name": "Rock_Slate_Cobble"
    },
    {
      "x": 4,
      "y": 1,
      "z": -1,
      "name": "Rock_Slate_Cobble"
    },
    {
      "x": 4,
      "y": 1,
      "z": 0,
      "name": "Rock_Slate_Cobble"
    },
    {
      "x": 4,
      "y": 0,
      "z": 1,
      "name": "Rock_Slate_Cobble"
    },
    {
      "x": 4,
      "y": 1,
      "z": 1,
      "name": "Rock_Slate_Cobble"
    }
  ],
  "fluids": [
    {
      "x": -3,
      "y": 0,
      "z": -3,
      "name": "Empty",
      "level": 0
    },
    {
      "x": -3,
      "y": 1,
      "z": -3,
      "name": "Empty",
      "level": 0
    },
    {
      "x": -3,
      "y": 2,
      "z": -3,
      "name": "Empty",
      "level": 0
    },
    {
      "x": -3,
      "y": 3,
      "z": -3,
      "name": "Empty",
      "level": 0
    },
    {
      "x": -3,
      "y": 4,
      "z": -3,
      "name": "Empty",
      "level": 0
    },
    {
      "x": -3,
      "y": 5,
      "z": -3,
      "name": "Empty",
      "level": 0
    },
    {
      "x": -3,
      "y": 6,
      "z": -3,
      "name": "Empty",
      "level": 0
    },
    {
      "x": -3,
      "y": 3,
      "z": -2,
      "name": "Empty",
      "level": 0
    },
    {
      "x": -3,
      "y": 5,
      "z": -2,
      "name": "Empty",
      "level": 0
    },
    {
      "x": -3,
      "y": 6,
      "z": -2,
      "name": "Empty",
      "level": 0
    },
    {
      "x": -3,
      "y": 6,
      "z": -1,
      "name": "Empty",
      "level": 0
    },
    {
      "x": -3,
      "y": 5,
      "z": 0,
      "name": "Empty",
      "level": 0
    },
    {
      "x": -3,
      "y": 6,
      "z": 0,
      "name": "Empty",
      "level": 0
    },
    {
      "x": -3,
      "y": 0,
      "z": 1,
      "name": "Empty",
      "level": 0
    },
    {
      "x": -3,
      "y": 1,
      "z": 1,
      "name": "Empty",
      "level": 0
    },
    {
      "x": -3,
      "y": 2,
      "z": 1,
      "name": "Empty",
      "level": 0
    },
    {
      "x": -3,
      "y": 3,
      "z": 1,
      "name": "Empty",
      "level": 0
    },
    {
      "x": -3,
      "y": 4,
      "z": 1,
      "name": "Empty",
      "level": 0
    },
    {
      "x": -3,
      "y": 5,
      "z": 1,
      "name": "Empty",
      "level": 0
    },
    {
      "x": -3,
      "y": 6,
      "z": 1,
      "name": "Empty",
      "level": 0
    },
    {
      "x": -3,
      "y": 7,
      "z": 1,
      "name": "Empty",
      "level": 0
    },
    {
      "x": -3,
      "y": 4,
      "z": 2,
      "name": "Empty",
      "level": 0
    },
    {
      "x": -3,
      "y": 3,
      "z": 3,
      "name": "Empty",
      "level": 0
    },
    {
      "x": -3,
      "y": 4,
      "z": 3,
      "name": "Empty",
      "level": 0
    },
    {
      "x": -3,
      "y": 0,
      "z": 4,
      "name": "Empty",
      "level": 0
    },
    {
      "x": -3,
      "y": 1,
      "z": 4,
      "name": "Empty",
      "level": 0
    },
    {
      "x": -3,
      "y": 2,
      "z": 4,
      "name": "Empty",
      "level": 0
    },
    {
      "x": -3,
      "y": 3,
      "z": 4,
      "name": "Empty",
      "level": 0
    },
    {
      "x": -3,
      "y": 4,
      "z": 4,
      "name": "Empty",
      "level": 0
    },
    {
      "x": -2,
      "y": 3,
      "z": -3,
      "name": "Empty",
      "level": 0
    },
    {
      "x": -2,
      "y": 2,
      "z": 1,
      "name": "Empty",
      "level": 0
    },
    {
      "x": -2,
      "y": 2,
      "z": 3,
      "name": "Empty",
      "level": 0
    },
    {
      "x": -2,
      "y": 2,
      "z": 4,
      "name": "Empty",
      "level": 0
    },
    {
      "x": -1,
      "y": 3,
      "z": -3,
      "name": "Empty",
      "level": 0
    },
    {
      "x": -1,
      "y": 4,
      "z": 1,
      "name": "Empty",
      "level": 0
    },
    {
      "x": -1,
      "y": 2,
      "z": 4,
      "name": "Empty",
      "level": 0
    },
    {
      "x": 0,
      "y": 0,
      "z": -3,
      "name": "Empty",
      "level": 0
    },
    {
      "x": 0,
      "y": 1,
      "z": -3,
      "name": "Empty",
      "level": 0
    },
    {
      "x": 0,
      "y": 2,
      "z": -3,
      "name": "Empty",
      "level": 0
    },
    {
      "x": 0,
      "y": 3,
      "z": -3,
      "name": "Empty",
      "level": 0
    },
    {
      "x": 0,
      "y": 4,
      "z": -3,
      "name": "Empty",
      "level": 0
    },
    {
      "x": 0,
      "y": 5,
      "z": -3,
      "name": "Empty",
      "level": 0
    },
    {
      "x": 0,
      "y": 3,
      "z": -2,
      "name": "Empty",
      "level": 0
    },
    {
      "x": 0,
      "y": 4,
      "z": -2,
      "name": "Empty",
      "level": 0
    },
    {
      "x": 0,
      "y": 4,
      "z": -1,
      "name": "Empty",
      "level": 0
    },
    {
      "x": 0,
      "y": 4,
      "z": 0,
      "name": "Empty",
      "level": 0
    },
    {
      "x": 0,
      "y": 4,
      "z": 1,
      "name": "Empty",
      "level": 0
    },
    {
      "x": 0,
      "y": 4,
      "z": 2,
      "name": "Empty",
      "level": 0
    },
    {
      "x": 0,
      "y": 3,
      "z": 3,
      "name": "Empty",
      "level": 0
    },
    {
      "x": 0,
      "y": 4,
      "z": 3,
      "name": "Empty",
      "level": 0
    },
    {
      "x": 0,
      "y": 2,
      "z": 4,
      "name": "Empty",
      "level": 0
    },
    {
      "x": 0,
      "y": 3,
      "z": 4,
      "name": "Empty",
      "level": 0
    },
    {
      "x": 0,
      "y": 4,
      "z": 4,
      "name": "Empty",
      "level": 0
    },
    {
      "x": 1,
      "y": 1,
      "z": -3,
      "name": "Empty",
      "level": 0
    },
    {
      "x": 1,
      "y": 4,
      "z": -3,
      "name": "Empty",
      "level": 0
    },
    {
      "x": 1,
      "y": 3,
      "z": 1,
      "name": "Empty",
      "level": 0
    },
    {
      "x": 1,
      "y": 4,
      "z": 1,
      "name": "Empty",
      "level": 0
    },
    {
      "x": 1,
      "y": 2,
      "z": 4,
      "name": "Empty",
      "level": 0
    },
    {
      "x": 2,
      "y": 0,
      "z": -3,
      "name": "Empty",
      "level": 0
    },
    {
      "x": 2,
      "y": 1,
      "z": -3,
      "name": "Empty",
      "level": 0
    },
    {
      "x": 2,
      "y": 4,
      "z": -3,
      "name": "Empty",
      "level": 0
    },
    {
      "x": 2,
      "y": 0,
      "z": 1,
      "name": "Empty",
      "level": 0
    },
    {
      "x": 2,
      "y": 1,
      "z": 1,
      "name": "Empty",
      "level": 0
    },
    {
      "x": 2,
      "y": 2,
      "z": 1,
      "name": "Empty",
      "level": 0
    },
    {
      "x": 2,
      "y": 3,
      "z": 1,
      "name": "Empty",
      "level": 0
    },
    {
      "x": 2,
      "y": 4,
      "z": 1,
      "name": "Empty",
      "level": 0
    },
    {
      "x": 2,
      "y": 0,
      "z": 2,
      "name": "Empty",
      "level": 0
    },
    {
      "x": 2,
      "y": 1,
      "z": 2,
      "name": "Empty",
      "level": 0
    },
    {
      "x": 2,
      "y": 2,
      "z": 4,
      "name": "Empty",
      "level": 0
    },
    {
      "x": 3,
      "y": 1,
      "z": -3,
      "name": "Empty",
      "level": 0
    },
    {
      "x": 3,
      "y": 4,
      "z": -3,
      "name": "Empty",
      "level": 0
    },
    {
      "x": 3,
      "y": 1,
      "z": 0,
      "name": "Empty",
      "level": 0
    },
    {
      "x": 3,
      "y": 1,
      "z": 1,
      "name": "Empty",
      "level": 0
    },
    {
      "x": 3,
      "y": 0,
      "z": 4,
      "name": "Empty",
      "level": 0
    },
    {
      "x": 3,
      "y": 1,
      "z": 4,
      "name": "Empty",
      "level": 0
    },
    {
      "x": 3,
      "y": 2,
      "z": 4,
      "name": "Empty",
      "level": 0
    },
    {
      "x": 4,
      "y": 0,
      "z": -3,
      "name": "Empty",
      "level": 0
    },
    {
      "x": 4,
      "y": 1,
      "z": -3,
      "name": "Empty",
      "level": 0
    },
    {
      "x": 4,
      "y": 2,
      "z": -3,
      "name": "Empty",
      "level": 0
    },
    {
      "x": 4,
      "y": 3,
      "z": -3,
      "name": "Empty",
      "level": 0
    },
    {
      "x": 4,
      "y": 4,
      "z": -3,
      "name": "Empty",
      "level": 0
    },
    {
      "x": 4,
      "y": 5,
      "z": -3,
      "name": "Empty",
      "level": 0
    },
    {
      "x": 4,
      "y": 1,
      "z": -2,
      "name": "Empty",
      "level": 0
    },
    {
      "x": 4,
      "y": 1,
      "z": -1,
      "name": "Empty",
      "level": 0
    },
    {
      "x": 4,
      "y": 1,
      "z": 0,
      "name": "Empty",
      "level": 0
    },
    {
      "x": 4,
      "y": 0,
      "z": 1,
      "name": "Empty",
      "level": 0
    },
    {
      "x": 4,
      "y": 1,
      "z": 1,
      "name": "Empty",
      "level": 0
    }
  ],
  "entities": [
    {
      "Components": {
        "Nameplate": {
          "Text": "Spider_Back"
        },
        "HiddenFromAdventurePlayer": {},
        "SpawnMarkerComponent": {
          "SpawnMarker": "Spider_Back",
          "RespawnTime": 1.0,
          "SpawnCount": 0
        },
        "Transform": {
          "Position": {
            "X": 0.10811589234083385,
            "Y": 0.0,
            "Z": 1.2557429389297567
          },
          "Rotation": {
            "Pitch": 0.0,
            "Yaw": 0.06825381517410278,
            "Roll": 0.0
          }
        },
        "Model": {
          "Model": {
            "Id": "NPC_Spawn_Marker",
            "Scale": 1.0
          }
        },
        "UUID": {
          "UUID": {
            "$binary": "Z7/4EMIPNjy9CfQkmB9Y/g==",
            "$type": "04"
          }
        },
        "HeadRotation": {
          "Rotation": {
            "Pitch": 0.0,
            "Yaw": 0.06825381517410278,
            "Roll": 0.0
          }
        }
      }
    }
  ]
}