{
  "version": 8,
  "blockIdVersion": 11,
  "anchorX": 0,
  "anchorY": 0,
  "anchorZ": 0,
  "blocks": [
    {
      "x": -12,
      "y": 8,
      "z": -12,
      "name": "Rock_Slate"
    },
    {
      "x": -12,
      "y": 9,
      "z": -12,
      "name": "Rock_Slate"
    },
    {
      "x": -12,
      "y": 10,
      "z": -12,
      "name": "Rock_Slate"
    },
    {
      "x": -12,
      "y": 11,
      "z": -12,
      "name": "Rock_Slate"
    },
    {
      "x": -12,
      "y": 12,
      "z": -12,
      "name": "Rock_Slate"
    },
    {
      "x": -12,
      "y": 13,
      "z": -12,
      "name": "Rock_Slate"
    },
    {
      "x": -12,
      "y": 14,
      "z": -12,
      "name": "Rock_Slate"
    },
    {
      "x": -12,
      "y": 15,
      "z": -12,
      "name": "Rock_Slate"
    },
    {
      "x": -12,
      "y": 16,
      "z": -12,
      "name": "Rock_Slate"
    },
    {
      "x": -12,
      "y": 17,
      "z": -12,
      "name": "Rock_Slate"
    },
    {
      "x": -12,
      "y": 18,
      "z": -12,
      "name": "Rock_Slate"
    },
    {
      "x": -12,
      "y": 19,
      "z": -12,
      "name": "Rock_Slate"
    },
    {
      "x": -12,
      "y": 20,
      "z": -12,
      "name": "Rock_Slate"
    },
    {
      "x": -12,
      "y": 21,
      "z": -12,
      "name": "Rock_Slate"
    },
    {
      "x": -12,
      "y": 22,
      "z": -12,
      "name": "Rock_Slate"
    },
    {
      "x": -12,
      "y": 23,
      "z": -12,
      "name": "Rock_Slate"
    },
    {
      "x": -12,
      "y": 24,
      "z": -12,
      "name": "Rock_Slate"
    },
    {
      "x": -12,
      "y": 25,
      "z": -12,
      "name": "Rock_Slate"
    },
    {
      "x": -12,
      "y": 26,
      "z": -12,
      "name": "Rock_Slate"
    },
    {
      "x": -12,
      "y": 27,
      "z": -12,
      "name": "Rock_Slate"
    },
    {
      "x": -12,
      "y": 28,
      "z": -12,
      "name": "Rock_Slate"
    },
    {
      "x": -12,
      "y": 29,
      "z": -12,
      "name": "Rock_Slate"
    },
    {
      "x": -12,
      "y": 30,
      "z": -12,
      "name": "Rock_Slate"
    },
    {
      "x": -12,
      "y": 31,
      "z": -12,
      "name": "Rock_Slate"
    },
    {
      "x": -12,
      "y": 32,
      "z": -12,
      "name": "Rock_Slate"
    },
    {
      "x": -12,
      "y": 8,
      "z": -11,
      "name": "Rock_Slate"
    },
    {
      "x": -12,
      "y": 9,
      "z": -11,
      "name": "Rock_Slate"
    },
    {
      "x": -12,
      "y": 10,
      "z": -11,
      "name": "Rock_Slate"
    },
    {
      "x": -12,
      "y": 11,
      "z": -11,
      "name": "Rock_Slate"
    },
    {
      "x": -12,
      "y": 12,
      "z": -11,
      "name": "Rock_Slate"
    },
    {
      "x": -12,
      "y": 13,
      "z": -11,
      "name": "Rock_Slate"
    },
    {
      "x": -12,
      "y": 14,
      "z": -11,
      "name": "Rock_Slate"
    },
    {
      "x": -12,
      "y": 15,
      "z": -11,
      "name": "Rock_Slate"
    },
    {
      "x": -12,
      "y": 16,
      "z": -11,
      "name": "Rock_Slate"
    },
    {
      "x": -12,
      "y": 17,
      "z": -11,
      "name": "Rock_Slate"
    },
    {
      "x": -12,
      "y": 18,
      "z": -11,
      "name": "Rock_Slate"
    },
    {
      "x": -12,
      "y": 19,
      "z": -11,
      "name": "Rock_Slate"
    },
    {
      "x": -12,
      "y": 20,
      "z": -11,
      "name": "Rock_Slate"
    },
    {
      "x": -12,
      "y": 21,
      "z": -11,
      "name": "Rock_Slate"
    },
    {
      "x": -12,
      "y": 22,
      "z": -11,
      "name": "Rock_Slate"
    },
    {
      "x": -12,
      "y": 23,
      "z": -11,
      "name": "Rock_Slate"
    },
    {
      "x": -12,
      "y": 24,
      "z": -11,
      "name": "Rock_Slate"
    },
    {
      "x": -12,
      "y": 25,
      "z": -11,
      "name": "Rock_Slate"
    },
    {
      "x": -12,
      "y": 26,
      "z": -11,
      "name": "Rock_Slate"
    },
    {
      "x": -12,
      "y": 27,
      "z": -11,
      "name": "Rock_Slate"
    },
    {
      "x": -12,
      "y": 28,
      "z": -11,
      "name": "Rock_Slate"
    },
    {
      "x": -12,
      "y": 29,
      "z": -11,
      "name": "Rock_Slate"
    },
    {
      "x": -12,
      "y": 30,
      "z": -11,
      "name": "Rock_Slate"
    },
    {
      "x": -12,
      "y": 31,
      "z": -11,
      "name": "Rock_Slate"
    },
    {
      "x": -12,
      "y": 32,
      "z": -11,
      "name": "Rock_Slate"
    },
    {
      "x": -12,
      "y": 9,
      "z": -10,
      "name": "Rock_Slate"
    },
    {
      "x": -12,
      "y": 10,
      "z": -10,
      "name": "Rock_Slate"
    },
    {
      "x": -12,
      "y": 11,
      "z": -10,
      "name": "Rock_Slate"
    },
    {
      "x": -12,
      "y": 12,
      "z": -10,
      "name": "Rock_Slate"
    },
    {
      "x": -12,
      "y": 13,
      "z": -10,
      "name": "Rock_Slate"
    },
    {
      "x": -12,
      "y": 14,
      "z": -10,
      "name": "Rock_Slate"
    },
    {
      "x": -12,
      "y": 15,
      "z": -10,
      "name": "Rock_Slate"
    },
    {
      "x": -12,
      "y": 16,
      "z": -10,
      "name": "Rock_Slate"
    },
    {
      "x": -12,
      "y": 17,
      "z": -10,
      "name": "Rock_Slate"
    },
    {
      "x": -12,
      "y": 18,
      "z": -10,
      "name": "Rock_Slate"
    },
    {
      "x": -12,
      "y": 19,
      "z": -10,
      "name": "Rock_Slate"
    },
    {
      "x": -12,
      "y": 20,
      "z": -10,
      "name": "Rock_Slate"
    },
    {
      "x": -12,
      "y": 21,
      "z": -10,
      "name": "Rock_Slate"
    },
    {
      "x": -12,
      "y": 22,
      "z": -10,
      "name": "Rock_Slate"
    },
    {
      "x": -12,
      "y": 23,
      "z": -10,
      "name": "Rock_Slate"
    },
    {
      "x": -12,
      "y": 24,
      "z": -10,
      "name": "Rock_Slate"
    },
    {
      "x": -12,
      "y": 25,
      "z": -10,
      "name": "Rock_Slate"
    },
    {
      "x": -12,
      "y": 26,
      "z": -10,
      "name": "Rock_Slate"
    },
    {
      "x": -12,
      "y": 27,
      "z": -10,
      "name": "Rock_Slate"
    },
    {
      "x": -12,
      "y": 28,
      "z": -10,
      "name": "Rock_Slate"
    },
    {
      "x": -12,
      "y": 29,
      "z": -10,
      "name": "Rock_Slate"
    },
    {
      "x": -12,
      "y": 30,
      "z": -10,
      "name": "Rock_Slate"
    },
    {
      "x": -12,
      "y": 31,
      "z": -10,
      "name": "Rock_Slate"
    },
    {
      "x": -12,
      "y": 29,
      "z": -9,
      "name": "Rock_Slate"
    },
    {
      "x": -12,
      "y": 30,
      "z": -9,
      "name": "Rock_Slate"
    },
    {
      "x": -12,
      "y": 31,
      "z": -9,
      "name": "Rock_Slate"
    },
    {
      "x": -12,
      "y": 32,
      "z": -9,
      "name": "Rock_Slate"
    },
    {
      "x": -12,
      "y": 31,
      "z": -8,
      "name": "Rock_Slate"
    },
    {
      "x": -12,
      "y": 30,
      "z": -7,
      "name": "Rock_Slate"
    },
    {
      "x": -12,
      "y": 31,
      "z": -7,
      "name": "Rock_Slate"
    },
    {
      "x": -12,
      "y": 8,
      "z": -6,
      "name": "Rock_Slate"
    },
    {
      "x": -12,
      "y": 9,
      "z": -6,
      "name": "Rock_Slate"
    },
    {
      "x": -12,
      "y": 10,
      "z": -6,
      "name": "Rock_Slate"
    },
    {
      "x": -12,
      "y": 11,
      "z": -6,
      "name": "Rock_Slate"
    },
    {
      "x": -12,
      "y": 12,
      "z": -6,
      "name": "Rock_Slate"
    },
    {
      "x": -12,
      "y": 13,
      "z": -6,
      "name": "Rock_Slate"
    },
    {
      "x": -12,
      "y": 14,
      "z": -6,
      "name": "Rock_Slate"
    },
    {
      "x": -12,
      "y": 15,
      "z": -6,
      "name": "Rock_Slate"
    },
    {
      "x": -12,
      "y": 16,
      "z": -6,
      "name": "Rock_Slate"
    },
    {
      "x": -12,
      "y": 17,
      "z": -6,
      "name": "Rock_Slate"
    },
    {
      "x": -12,
      "y": 18,
      "z": -6,
      "name": "Rock_Slate"
    },
    {
      "x": -12,
      "y": 19,
      "z": -6,
      "name": "Rock_Slate"
    },
    {
      "x": -12,
      "y": 20,
      "z": -6,
      "name": "Rock_Slate"
    },
    {
      "x": -12,
      "y": 21,
      "z": -6,
      "name": "Rock_Slate"
    },
    {
      "x": -12,
      "y": 22,
      "z": -6,
      "name": "Rock_Slate"
    },
    {
      "x": -12,
      "y": 23,
      "z": -6,
      "name": "Rock_Slate"
    },
    {
      "x": -12,
      "y": 24,
      "z": -6,
      "name": "Rock_Slate"
    },
    {
      "x": -12,
      "y": 25,
      "z": -6,
      "name": "Rock_Slate"
    },
    {
      "x": -12,
      "y": 26,
      "z": -6,
      "name": "Rock_Slate"
    },
    {
      "x": -12,
      "y": 27,
      "z": -6,
      "name": "Rock_Slate"
    },
    {
      "x": -12,
      "y": 28,
      "z": -6,
      "name": "Rock_Slate"
    },
    {
      "x": -12,
      "y": 29,
      "z": -6,
      "name": "Rock_Slate"
    },
    {
      "x": -12,
      "y": 30,
      "z": -6,
      "name": "Rock_Slate"
    },
    {
      "x": -12,
      "y": 31,
      "z": -6,
      "name": "Rock_Slate"
    },
    {
      "x": -12,
      "y": 32,
      "z": -6,
      "name": "Rock_Slate"
    },
    {
      "x": -12,
      "y": 28,
      "z": -5,
      "name": "Rock_Slate"
    },
    {
      "x": -12,
      "y": 29,
      "z": -5,
      "name": "Rock_Slate"
    },
    {
      "x": -12,
      "y": 30,
      "z": -5,
      "name": "Rock_Slate"
    },
    {
      "x": -12,
      "y": 31,
      "z": -5,
      "name": "Rock_Slate"
    },
    {
      "x": -12,
      "y": 32,
      "z": -5,
      "name": "Rock_Slate"
    },
    {
      "x": -12,
      "y": 26,
      "z": -4,
      "name": "Rock_Slate"
    },
    {
      "x": -12,
      "y": 27,
      "z": -4,
      "name": "Rock_Slate"
    },
    {
      "x": -12,
      "y": 28,
      "z": -4,
      "name": "Rock_Slate"
    },
    {
      "x": -12,
      "y": 29,
      "z": -4,
      "name": "Rock_Slate"
    },
    {
      "x": -12,
      "y": 30,
      "z": -4,
      "name": "Rock_Slate"
    },
    {
      "x": -12,
      "y": 31,
      "z": -4,
      "name": "Rock_Slate"
    },
    {
      "x": -12,
      "y": 32,
      "z": -4,
      "name": "Rock_Slate"
    },
    {
      "x": -12,
      "y": 27,
      "z": -3,
      "name": "Rock_Slate"
    },
    {
      "x": -12,
      "y": 28,
      "z": -3,
      "name": "Rock_Slate"
    },
    {
      "x": -12,
      "y": 29,
      "z": -3,
      "name": "Rock_Slate"
    },
    {
      "x": -12,
      "y": 30,
      "z": -3,
      "name": "Rock_Slate"
    },
    {
      "x": -12,
      "y": 31,
      "z": -3,
      "name": "Rock_Slate"
    },
    {
      "x": -12,
      "y": 10,
      "z": -2,
      "name": "Rock_Slate"
    },
    {
      "x": -12,
      "y": 11,
      "z": -2,
      "name": "Rock_Slate"
    },
    {
      "x": -12,
      "y": 12,
      "z": -2,
      "name": "Rock_Slate"
    },
    {
      "x": -12,
      "y": 13,
      "z": -2,
      "name": "Rock_Slate"
    },
    {
      "x": -12,
      "y": 14,
      "z": -2,
      "name": "Rock_Slate"
    },
    {
      "x": -12,
      "y": 15,
      "z": -2,
      "name": "Rock_Slate"
    },
    {
      "x": -12,
      "y": 16,
      "z": -2,
      "name": "Rock_Slate"
    },
    {
      "x": -12,
      "y": 17,
      "z": -2,
      "name": "Rock_Slate"
    },
    {
      "x": -12,
      "y": 18,
      "z": -2,
      "name": "Rock_Slate"
    },
    {
      "x": -12,
      "y": 19,
      "z": -2,
      "name": "Rock_Slate"
    },
    {
      "x": -12,
      "y": 20,
      "z": -2,
      "name": "Rock_Slate"
    },
    {
      "x": -12,
      "y": 21,
      "z": -2,
      "name": "Rock_Slate"
    },
    {
      "x": -12,
      "y": 22,
      "z": -2,
      "name": "Rock_Slate"
    },
    {
      "x": -12,
      "y": 23,
      "z": -2,
      "name": "Rock_Slate"
    },
    {
      "x": -12,
      "y": 24,
      "z": -2,
      "name": "Rock_Slate"
    },
    {
      "x": -12,
      "y": 25,
      "z": -2,
      "name": "Rock_Slate"
    },
    {
      "x": -12,
      "y": 26,
      "z": -2,
      "name": "Rock_Slate"
    },
    {
      "x": -12,
      "y": 27,
      "z": -2,
      "name": "Rock_Slate"
    },
    {
      "x": -12,
      "y": 28,
      "z": -2,
      "name": "Rock_Slate"
    },
    {
      "x": -12,
      "y": 29,
      "z": -2,
      "name": "Rock_Slate"
    },
    {
      "x": -12,
      "y": 30,
      "z": -2,
      "name": "Rock_Slate"
    },
    {
      "x": -12,
      "y": 31,
      "z": -2,
      "name": "Rock_Slate"
    },
    {
      "x": -12,
      "y": 32,
      "z": -2,
      "name": "Rock_Slate"
    },
    {
      "x": -12,
      "y": 29,
      "z": -1,
      "name": "Rock_Slate"
    },
    {
      "x": -12,
      "y": 30,
      "z": -1,
      "name": "Rock_Slate"
    },
    {
      "x": -12,
      "y": 31,
      "z": -1,
      "name": "Rock_Slate"
    },
    {
      "x": -12,
      "y": 29,
      "z": 0,
      "name": "Rock_Slate"
    },
    {
      "x": -12,
      "y": 30,
      "z": 0,
      "name": "Rock_Slate"
    },
    {
      "x": -12,
      "y": 31,
      "z": 0,
      "name": "Rock_Slate"
    },
    {
      "x": -12,
      "y": 30,
      "z": 1,
      "name": "Rock_Slate"
    },
    {
      "x": -12,
      "y": 31,
      "z": 1,
      "name": "Rock_Slate"
    },
    {
      "x": -12,
      "y": 32,
      "z": 1,
      "name": "Rock_Slate"
    },
    {
      "x": -12,
      "y": 8,
      "z": 2,
      "name": "Rock_Slate"
    },
    {
      "x": -12,
      "y": 9,
      "z": 2,
      "name": "Rock_Slate"
    },
    {
      "x": -12,
      "y": 10,
      "z": 2,
      "name": "Rock_Slate"
    },
    {
      "x": -12,
      "y": 11,
      "z": 2,
      "name": "Rock_Slate"
    },
    {
      "x": -12,
      "y": 12,
      "z": 2,
      "name": "Rock_Slate"
    },
    {
      "x": -12,
      "y": 13,
      "z": 2,
      "name": "Rock_Slate"
    },
    {
      "x": -12,
      "y": 14,
      "z": 2,
      "name": "Rock_Slate"
    },
    {
      "x": -12,
      "y": 15,
      "z": 2,
      "name": "Rock_Slate"
    },
    {
      "x": -12,
      "y": 16,
      "z": 2,
      "name": "Rock_Slate"
    },
    {
      "x": -12,
      "y": 17,
      "z": 2,
      "name": "Rock_Slate"
    },
    {
      "x": -12,
      "y": 18,
      "z": 2,
      "name": "Rock_Slate"
    },
    {
      "x": -12,
      "y": 19,
      "z": 2,
      "name": "Rock_Slate"
    },
    {
      "x": -12,
      "y": 20,
      "z": 2,
      "name": "Rock_Slate"
    },
    {
      "x": -12,
      "y": 21,
      "z": 2,
      "name": "Rock_Slate"
    },
    {
      "x": -12,
      "y": 22,
      "z": 2,
      "name": "Rock_Slate"
    },
    {
      "x": -12,
      "y": 23,
      "z": 2,
      "name": "Rock_Slate"
    },
    {
      "x": -12,
      "y": 24,
      "z": 2,
      "name": "Rock_Slate"
    },
    {
      "x": -12,
      "y": 25,
      "z": 2,
      "name": "Rock_Slate"
    },
    {
      "x": -12,
      "y": 26,
      "z": 2,
      "name": "Rock_Slate"
    },
    {
      "x": -12,
      "y": 27,
      "z": 2,
      "name": "Rock_Slate"
    },
    {
      "x": -12,
      "y": 28,
      "z": 2,
      "name": "Rock_Slate"
    },
    {
      "x": -12,
      "y": 29,
      "z": 2,
      "name": "Rock_Slate"
    },
    {
      "x": -12,
      "y": 30,
      "z": 2,
      "name": "Rock_Slate"
    },
    {
      "x": -12,
      "y": 31,
      "z": 2,
      "name": "Rock_Slate"
    },
    {
      "x": -12,
      "y": 32,
      "z": 2,
      "name": "Rock_Slate"
    },
    {
      "x": -12,
      "y": 26,
      "z": 3,
      "name": "Rock_Slate"
    },
    {
      "x": -12,
      "y": 27,
      "z": 3,
      "name": "Rock_Slate"
    },
    {
      "x": -12,
      "y": 28,
      "z": 3,
      "name": "Rock_Slate"
    },
    {
      "x": -12,
      "y": 29,
      "z": 3,
      "name": "Rock_Slate"
    },
    {
      "x": -12,
      "y": 30,
      "z": 3,
      "name": "Rock_Slate"
    },
    {
      "x": -12,
      "y": 31,
      "z": 3,
      "name": "Rock_Slate"
    },
    {
      "x": -12,
      "y": 32,
      "z": 3,
      "name": "Rock_Slate"
    },
    {
      "x": -12,
      "y": 29,
      "z": 4,
      "name": "Rock_Slate"
    },
    {
      "x": -12,
      "y": 30,
      "z": 4,
      "name": "Rock_Slate"
    },
    {
      "x": -12,
      "y": 31,
      "z": 4,
      "name": "Rock_Slate"
    },
    {
      "x": -12,
      "y": 28,
      "z": 5,
      "name": "Rock_Slate"
    },
    {
      "x": -12,
      "y": 29,
      "z": 5,
      "name": "Rock_Slate"
    },
    {
      "x": -12,
      "y": 30,
      "z": 5,
      "name": "Rock_Slate"
    },
    {
      "x": -12,
      "y": 31,
      "z": 5,
      "name": "Rock_Slate"
    },
    {
      "x": -12,
      "y": 32,
      "z": 5,
      "name": "Rock_Slate"
    },
    {
      "x": -12,
      "y": 10,
      "z": 6,
      "name": "Rock_Slate"
    },
    {
      "x": -12,
      "y": 11,
      "z": 6,
      "name": "Rock_Slate"
    },
    {
      "x": -12,
      "y": 12,
      "z": 6,
      "name": "Rock_Slate"
    },
    {
      "x": -12,
      "y": 13,
      "z": 6,
      "name": "Rock_Slate"
    },
    {
      "x": -12,
      "y": 14,
      "z": 6,
      "name": "Rock_Slate"
    },
    {
      "x": -12,
      "y": 15,
      "z": 6,
      "name": "Rock_Slate"
    },
    {
      "x": -12,
      "y": 16,
      "z": 6,
      "name": "Rock_Slate"
    },
    {
      "x": -12,
      "y": 17,
      "z": 6,
      "name": "Rock_Slate"
    },
    {
      "x": -12,
      "y": 18,
      "z": 6,
      "name": "Rock_Slate"
    },
    {
      "x": -12,
      "y": 19,
      "z": 6,
      "name": "Rock_Slate"
    },
    {
      "x": -12,
      "y": 20,
      "z": 6,
      "name": "Rock_Slate"
    },
    {
      "x": -12,
      "y": 21,
      "z": 6,
      "name": "Rock_Slate"
    },
    {
      "x": -12,
      "y": 22,
      "z": 6,
      "name": "Rock_Slate"
    },
    {
      "x": -12,
      "y": 23,
      "z": 6,
      "name": "Rock_Slate"
    },
    {
      "x": -12,
      "y": 24,
      "z": 6,
      "name": "Rock_Slate"
    },
    {
      "x": -12,
      "y": 25,
      "z": 6,
      "name": "Rock_Slate"
    },
    {
      "x": -12,
      "y": 26,
      "z": 6,
      "name": "Rock_Slate"
    },
    {
      "x": -12,
      "y": 27,
      "z": 6,
      "name": "Rock_Slate"
    },
    {
      "x": -12,
      "y": 28,
      "z": 6,
      "name": "Rock_Slate"
    },
    {
      "x": -12,
      "y": 29,
      "z": 6,
      "name": "Rock_Slate"
    },
    {
      "x": -12,
      "y": 30,
      "z": 6,
      "name": "Rock_Slate"
    },
    {
      "x": -12,
      "y": 31,
      "z": 6,
      "name": "Rock_Slate"
    },
    {
      "x": -12,
      "y": 29,
      "z": 7,
      "name": "Rock_Slate"
    },
    {
      "x": -12,
      "y": 30,
      "z": 7,
      "name": "Rock_Slate"
    },
    {
      "x": -12,
      "y": 31,
      "z": 7,
      "name": "Rock_Slate"
    },
    {
      "x": -12,
      "y": 30,
      "z": 8,
      "name": "Rock_Slate"
    },
    {
      "x": -12,
      "y": 31,
      "z": 8,
      "name": "Rock_Slate"
    },
    {
      "x": -12,
      "y": 28,
      "z": 9,
      "name": "Rock_Slate"
    },
    {
      "x": -12,
      "y": 29,
      "z": 9,
      "name": "Rock_Slate"
    },
    {
      "x": -12,
      "y": 30,
      "z": 9,
      "name": "Rock_Slate"
    },
    {
      "x": -12,
      "y": 31,
      "z": 9,
      "name": "Rock_Slate"
    },
    {
      "x": -12,
      "y": 32,
      "z": 9,
      "name": "Rock_Slate"
    },
    {
      "x": -12,
      "y": 9,
      "z": 10,
      "name": "Rock_Slate"
    },
    {
      "x": -12,
      "y": 10,
      "z": 10,
      "name": "Rock_Slate"
    },
    {
      "x": -12,
      "y": 11,
      "z": 10,
      "name": "Rock_Slate"
    },
    {
      "x": -12,
      "y": 12,
      "z": 10,
      "name": "Rock_Slate"
    },
    {
      "x": -12,
      "y": 13,
      "z": 10,
      "name": "Rock_Slate"
    },
    {
      "x": -12,
      "y": 14,
      "z": 10,
      "name": "Rock_Slate"
    },
    {
      "x": -12,
      "y": 15,
      "z": 10,
      "name": "Rock_Slate"
    },
    {
      "x": -12,
      "y": 16,
      "z": 10,
      "name": "Rock_Slate"
    },
    {
      "x": -12,
      "y": 17,
      "z": 10,
      "name": "Rock_Slate"
    },
    {
      "x": -12,
      "y": 18,
      "z": 10,
      "name": "Rock_Slate"
    },
    {
      "x": -12,
      "y": 19,
      "z": 10,
      "name": "Rock_Slate"
    },
    {
      "x": -12,
      "y": 20,
      "z": 10,
      "name": "Rock_Slate"
    },
    {
      "x": -12,
      "y": 21,
      "z": 10,
      "name": "Rock_Slate"
    },
    {
      "x": -12,
      "y": 22,
      "z": 10,
      "name": "Rock_Slate"
    },
    {
      "x": -12,
      "y": 23,
      "z": 10,
      "name": "Rock_Slate"
    },
    {
      "x": -12,
      "y": 24,
      "z": 10,
      "name": "Rock_Slate"
    },
    {
      "x": -12,
      "y": 25,
      "z": 10,
      "name": "Rock_Slate"
    },
    {
      "x": -12,
      "y": 26,
      "z": 10,
      "name": "Rock_Slate"
    },
    {
      "x": -12,
      "y": 27,
      "z": 10,
      "name": "Rock_Slate"
    },
    {
      "x": -12,
      "y": 28,
      "z": 10,
      "name": "Rock_Slate"
    },
    {
      "x": -12,
      "y": 29,
      "z": 10,
      "name": "Rock_Slate"
    },
    {
      "x": -12,
      "y": 30,
      "z": 10,
      "name": "Rock_Slate"
    },
    {
      "x": -12,
      "y": 31,
      "z": 10,
      "name": "Rock_Slate"
    },
    {
      "x": -12,
      "y": 32,
      "z": 10,
      "name": "Rock_Slate"
    },
    {
      "x": -12,
      "y": 8,
      "z": 11,
      "name": "Rock_Slate"
    },
    {
      "x": -12,
      "y": 9,
      "z": 11,
      "name": "Rock_Slate"
    },
    {
      "x": -12,
      "y": 10,
      "z": 11,
      "name": "Rock_Slate"
    },
    {
      "x": -12,
      "y": 11,
      "z": 11,
      "name": "Rock_Slate"
    },
    {
      "x": -12,
      "y": 12,
      "z": 11,
      "name": "Rock_Slate"
    },
    {
      "x": -12,
      "y": 13,
      "z": 11,
      "name": "Rock_Slate"
    },
    {
      "x": -12,
      "y": 14,
      "z": 11,
      "name": "Rock_Slate"
    },
    {
      "x": -12,
      "y": 15,
      "z": 11,
      "name": "Rock_Slate"
    },
    {
      "x": -12,
      "y": 16,
      "z": 11,
      "name": "Rock_Slate"
    },
    {
      "x": -12,
      "y": 17,
      "z": 11,
      "name": "Rock_Slate"
    },
    {
      "x": -12,
      "y": 18,
      "z": 11,
      "name": "Rock_Slate"
    },
    {
      "x": -12,
      "y": 19,
      "z": 11,
      "name": "Rock_Slate"
    },
    {
      "x": -12,
      "y": 20,
      "z": 11,
      "name": "Rock_Slate"
    },
    {
      "x": -12,
      "y": 21,
      "z": 11,
      "name": "Rock_Slate"
    },
    {
      "x": -12,
      "y": 22,
      "z": 11,
      "name": "Rock_Slate"
    },
    {
      "x": -12,
      "y": 23,
      "z": 11,
      "name": "Rock_Slate"
    },
    {
      "x": -12,
      "y": 24,
      "z": 11,
      "name": "Rock_Slate"
    },
    {
      "x": -12,
      "y": 25,
      "z": 11,
      "name": "Rock_Slate"
    },
    {
      "x": -12,
      "y": 26,
      "z": 11,
      "name": "Rock_Slate"
    },
    {
      "x": -12,
      "y": 27,
      "z": 11,
      "name": "Rock_Slate"
    },
    {
      "x": -12,
      "y": 28,
      "z": 11,
      "name": "Rock_Slate"
    },
    {
      "x": -12,
      "y": 29,
      "z": 11,
      "name": "Rock_Slate"
    },
    {
      "x": -12,
      "y": 30,
      "z": 11,
      "name": "Rock_Slate"
    },
    {
      "x": -12,
      "y": 31,
      "z": 11,
      "name": "Rock_Slate"
    },
    {
      "x": -12,
      "y": 8,
      "z": 12,
      "name": "Rock_Slate"
    },
    {
      "x": -12,
      "y": 9,
      "z": 12,
      "name": "Rock_Slate"
    },
    {
      "x": -12,
      "y": 10,
      "z": 12,
      "name": "Rock_Slate"
    },
    {
      "x": -12,
      "y": 11,
      "z": 12,
      "name": "Rock_Slate"
    },
    {
      "x": -12,
      "y": 12,
      "z": 12,
      "name": "Rock_Slate"
    },
    {
      "x": -12,
      "y": 13,
      "z": 12,
      "name": "Rock_Slate"
    },
    {
      "x": -12,
      "y": 14,
      "z": 12,
      "name": "Rock_Slate"
    },
    {
      "x": -12,
      "y": 15,
      "z": 12,
      "name": "Rock_Slate"
    },
    {
      "x": -12,
      "y": 16,
      "z": 12,
      "name": "Rock_Slate"
    },
    {
      "x": -12,
      "y": 17,
      "z": 12,
      "name": "Rock_Slate"
    },
    {
      "x": -12,
      "y": 18,
      "z": 12,
      "name": "Rock_Slate"
    },
    {
      "x": -12,
      "y": 19,
      "z": 12,
      "name": "Rock_Slate"
    },
    {
      "x": -12,
      "y": 20,
      "z": 12,
      "name": "Rock_Slate"
    },
    {
      "x": -12,
      "y": 21,
      "z": 12,
      "name": "Rock_Slate"
    },
    {
      "x": -12,
      "y": 22,
      "z": 12,
      "name": "Rock_Slate"
    },
    {
      "x": -12,
      "y": 23,
      "z": 12,
      "name": "Rock_Slate"
    },
    {
      "x": -12,
      "y": 24,
      "z": 12,
      "name": "Rock_Slate"
    },
    {
      "x": -12,
      "y": 25,
      "z": 12,
      "name": "Rock_Slate"
    },
    {
      "x": -12,
      "y": 26,
      "z": 12,
      "name": "Rock_Slate"
    },
    {
      "x": -12,
      "y": 27,
      "z": 12,
      "name": "Rock_Slate"
    },
    {
      "x": -12,
      "y": 28,
      "z": 12,
      "name": "Rock_Slate"
    },
    {
      "x": -12,
      "y": 29,
      "z": 12,
      "name": "Rock_Slate"
    },
    {
      "x": -12,
      "y": 30,
      "z": 12,
      "name": "Rock_Slate"
    },
    {
      "x": -12,
      "y": 31,
      "z": 12,
      "name": "Rock_Slate"
    },
    {
      "x": -12,
      "y": 32,
      "z": 12,
      "name": "Rock_Slate"
    },
    {
      "x": -11,
      "y": 9,
      "z": -12,
      "name": "Rock_Slate"
    },
    {
      "x": -11,
      "y": 10,
      "z": -12,
      "name": "Rock_Slate"
    },
    {
      "x": -11,
      "y": 11,
      "z": -12,
      "name": "Rock_Slate"
    },
    {
      "x": -11,
      "y": 12,
      "z": -12,
      "name": "Rock_Slate"
    },
    {
      "x": -11,
      "y": 13,
      "z": -12,
      "name": "Rock_Slate"
    },
    {
      "x": -11,
      "y": 14,
      "z": -12,
      "name": "Rock_Slate"
    },
    {
      "x": -11,
      "y": 15,
      "z": -12,
      "name": "Rock_Slate"
    },
    {
      "x": -11,
      "y": 16,
      "z": -12,
      "name": "Rock_Slate"
    },
    {
      "x": -11,
      "y": 17,
      "z": -12,
      "name": "Rock_Slate"
    },
    {
      "x": -11,
      "y": 18,
      "z": -12,
      "name": "Rock_Slate"
    },
    {
      "x": -11,
      "y": 19,
      "z": -12,
      "name": "Rock_Slate"
    },
    {
      "x": -11,
      "y": 20,
      "z": -12,
      "name": "Rock_Slate"
    },
    {
      "x": -11,
      "y": 21,
      "z": -12,
      "name": "Rock_Slate"
    },
    {
      "x": -11,
      "y": 22,
      "z": -12,
      "name": "Rock_Slate"
    },
    {
      "x": -11,
      "y": 23,
      "z": -12,
      "name": "Rock_Slate"
    },
    {
      "x": -11,
      "y": 24,
      "z": -12,
      "name": "Rock_Slate"
    },
    {
      "x": -11,
      "y": 25,
      "z": -12,
      "name": "Rock_Slate"
    },
    {
      "x": -11,
      "y": 26,
      "z": -12,
      "name": "Rock_Slate"
    },
    {
      "x": -11,
      "y": 27,
      "z": -12,
      "name": "Rock_Slate"
    },
    {
      "x": -11,
      "y": 28,
      "z": -12,
      "name": "Rock_Slate"
    },
    {
      "x": -11,
      "y": 29,
      "z": -12,
      "name": "Rock_Slate"
    },
    {
      "x": -11,
      "y": 30,
      "z": -12,
      "name": "Rock_Slate"
    },
    {
      "x": -11,
      "y": 31,
      "z": -12,
      "name": "Rock_Slate"
    },
    {
      "x": -11,
      "y": 32,
      "z": -12,
      "name": "Rock_Slate"
    },
    {
      "x": -11,
      "y": 29,
      "z": -11,
      "name": "Ore_Server"
    },
    {
      "x": -11,
      "y": 31,
      "z": -10,
      "name": "Ore_Server"
    },
    {
      "x": -11,
      "y": 29,
      "z": 2,
      "name": "Ore_Server"
    },
    {
      "x": -11,
      "y": 30,
      "z": 9,
      "name": "Ore_Server"
    },
    {
      "x": -11,
      "y": 29,
      "z": 11,
      "name": "Ore_Server"
    },
    {
      "x": -11,
      "y": 25,
      "z": 12,
      "name": "Rock_Slate"
    },
    {
      "x": -11,
      "y": 26,
      "z": 12,
      "name": "Rock_Slate"
    },
    {
      "x": -11,
      "y": 27,
      "z": 12,
      "name": "Rock_Slate"
    },
    {
      "x": -11,
      "y": 28,
      "z": 12,
      "name": "Rock_Slate"
    },
    {
      "x": -11,
      "y": 29,
      "z": 12,
      "name": "Rock_Slate"
    },
    {
      "x": -11,
      "y": 30,
      "z": 12,
      "name": "Rock_Slate"
    },
    {
      "x": -11,
      "y": 31,
      "z": 12,
      "name": "Rock_Slate"
    },
    {
      "x": -11,
      "y": 32,
      "z": 12,
      "name": "Rock_Slate"
    },
    {
      "x": -10,
      "y": 27,
      "z": -12,
      "name": "Rock_Slate"
    },
    {
      "x": -10,
      "y": 28,
      "z": -12,
      "name": "Rock_Slate"
    },
    {
      "x": -10,
      "y": 29,
      "z": -12,
      "name": "Rock_Slate"
    },
    {
      "x": -10,
      "y": 30,
      "z": -12,
      "name": "Rock_Slate"
    },
    {
      "x": -10,
      "y": 31,
      "z": -12,
      "name": "Rock_Slate"
    },
    {
      "x": -10,
      "y": 8,
      "z": 12,
      "name": "Rock_Slate"
    },
    {
      "x": -10,
      "y": 9,
      "z": 12,
      "name": "Rock_Slate"
    },
    {
      "x": -10,
      "y": 10,
      "z": 12,
      "name": "Rock_Slate"
    },
    {
      "x": -10,
      "y": 11,
      "z": 12,
      "name": "Rock_Slate"
    },
    {
      "x": -10,
      "y": 12,
      "z": 12,
      "name": "Rock_Slate"
    },
    {
      "x": -10,
      "y": 13,
      "z": 12,
      "name": "Rock_Slate"
    },
    {
      "x": -10,
      "y": 14,
      "z": 12,
      "name": "Rock_Slate"
    },
    {
      "x": -10,
      "y": 15,
      "z": 12,
      "name": "Rock_Slate"
    },
    {
      "x": -10,
      "y": 16,
      "z": 12,
      "name": "Rock_Slate"
    },
    {
      "x": -10,
      "y": 17,
      "z": 12,
      "name": "Rock_Slate"
    },
    {
      "x": -10,
      "y": 18,
      "z": 12,
      "name": "Rock_Slate"
    },
    {
      "x": -10,
      "y": 19,
      "z": 12,
      "name": "Rock_Slate"
    },
    {
      "x": -10,
      "y": 20,
      "z": 12,
      "name": "Rock_Slate"
    },
    {
      "x": -10,
      "y": 21,
      "z": 12,
      "name": "Rock_Slate"
    },
    {
      "x": -10,
      "y": 22,
      "z": 12,
      "name": "Rock_Slate"
    },
    {
      "x": -10,
      "y": 23,
      "z": 12,
      "name": "Rock_Slate"
    },
    {
      "x": -10,
      "y": 24,
      "z": 12,
      "name": "Rock_Slate"
    },
    {
      "x": -10,
      "y": 25,
      "z": 12,
      "name": "Rock_Slate"
    },
    {
      "x": -10,
      "y": 26,
      "z": 12,
      "name": "Rock_Slate"
    },
    {
      "x": -10,
      "y": 27,
      "z": 12,
      "name": "Rock_Slate"
    },
    {
      "x": -10,
      "y": 28,
      "z": 12,
      "name": "Rock_Slate"
    },
    {
      "x": -10,
      "y": 29,
      "z": 12,
      "name": "Rock_Slate"
    },
    {
      "x": -10,
      "y": 30,
      "z": 12,
      "name": "Rock_Slate"
    },
    {
      "x": -10,
      "y": 31,
      "z": 12,
      "name": "Rock_Slate"
    },
    {
      "x": -10,
      "y": 32,
      "z": 12,
      "name": "Rock_Slate"
    },
    {
      "x": -9,
      "y": 28,
      "z": -12,
      "name": "Rock_Slate"
    },
    {
      "x": -9,
      "y": 29,
      "z": -12,
      "name": "Rock_Slate"
    },
    {
      "x": -9,
      "y": 30,
      "z": -12,
      "name": "Rock_Slate"
    },
    {
      "x": -9,
      "y": 31,
      "z": -12,
      "name": "Rock_Slate"
    },
    {
      "x": -9,
      "y": 32,
      "z": -12,
      "name": "Rock_Slate"
    },
    {
      "x": -9,
      "y": 31,
      "z": -11,
      "name": "Ore_Server"
    },
    {
      "x": -9,
      "y": 31,
      "z": 11,
      "name": "Ore_Server"
    },
    {
      "x": -9,
      "y": 28,
      "z": 12,
      "name": "Rock_Slate"
    },
    {
      "x": -9,
      "y": 29,
      "z": 12,
      "name": "Rock_Slate"
    },
    {
      "x": -9,
      "y": 30,
      "z": 12,
      "name": "Rock_Slate"
    },
    {
      "x": -9,
      "y": 31,
      "z": 12,
      "name": "Rock_Slate"
    },
    {
      "x": -9,
      "y": 32,
      "z": 12,
      "name": "Rock_Slate"
    },
    {
      "x": -8,
      "y": 29,
      "z": -12,
      "name": "Rock_Slate"
    },
    {
      "x": -8,
      "y": 30,
      "z": -12,
      "name": "Rock_Slate"
    },
    {
      "x": -8,
      "y": 31,
      "z": -12,
      "name": "Rock_Slate"
    },
    {
      "x": -8,
      "y": 32,
      "z": -12,
      "name": "Rock_Slate"
    },
    {
      "x": -8,
      "y": 27,
      "z": 12,
      "name": "Rock_Slate"
    },
    {
      "x": -8,
      "y": 28,
      "z": 12,
      "name": "Rock_Slate"
    },
    {
      "x": -8,
      "y": 29,
      "z": 12,
      "name": "Rock_Slate"
    },
    {
      "x": -8,
      "y": 30,
      "z": 12,
      "name": "Rock_Slate"
    },
    {
      "x": -8,
      "y": 31,
      "z": 12,
      "name": "Rock_Slate"
    },
    {
      "x": -7,
      "y": 9,
      "z": -12,
      "name": "Rock_Slate"
    },
    {
      "x": -7,
      "y": 11,
      "z": -12,
      "name": "Rock_Slate"
    },
    {
      "x": -7,
      "y": 12,
      "z": -12,
      "name": "Rock_Slate"
    },
    {
      "x": -7,
      "y": 13,
      "z": -12,
      "name": "Rock_Slate"
    },
    {
      "x": -7,
      "y": 14,
      "z": -12,
      "name": "Rock_Slate"
    },
    {
      "x": -7,
      "y": 15,
      "z": -12,
      "name": "Rock_Slate"
    },
    {
      "x": -7,
      "y": 16,
      "z": -12,
      "name": "Rock_Slate"
    },
    {
      "x": -7,
      "y": 17,
      "z": -12,
      "name": "Rock_Slate"
    },
    {
      "x": -7,
      "y": 18,
      "z": -12,
      "name": "Rock_Slate"
    },
    {
      "x": -7,
      "y": 19,
      "z": -12,
      "name": "Rock_Slate"
    },
    {
      "x": -7,
      "y": 20,
      "z": -12,
      "name": "Rock_Slate"
    },
    {
      "x": -7,
      "y": 21,
      "z": -12,
      "name": "Rock_Slate"
    },
    {
      "x": -7,
      "y": 22,
      "z": -12,
      "name": "Rock_Slate"
    },
    {
      "x": -7,
      "y": 23,
      "z": -12,
      "name": "Rock_Slate"
    },
    {
      "x": -7,
      "y": 24,
      "z": -12,
      "name": "Rock_Slate"
    },
    {
      "x": -7,
      "y": 25,
      "z": -12,
      "name": "Rock_Slate"
    },
    {
      "x": -7,
      "y": 26,
      "z": -12,
      "name": "Rock_Slate"
    },
    {
      "x": -7,
      "y": 27,
      "z": -12,
      "name": "Rock_Slate"
    },
    {
      "x": -7,
      "y": 28,
      "z": -12,
      "name": "Rock_Slate"
    },
    {
      "x": -7,
      "y": 29,
      "z": -12,
      "name": "Rock_Slate"
    },
    {
      "x": -7,
      "y": 30,
      "z": -12,
      "name": "Rock_Slate"
    },
    {
      "x": -7,
      "y": 31,
      "z": -12,
      "name": "Rock_Slate"
    },
    {
      "x": -7,
      "y": 32,
      "z": -12,
      "name": "Rock_Slate"
    },
    {
      "x": -7,
      "y": 26,
      "z": 12,
      "name": "Rock_Slate"
    },
    {
      "x": -7,
      "y": 27,
      "z": 12,
      "name": "Rock_Slate"
    },
    {
      "x": -7,
      "y": 28,
      "z": 12,
      "name": "Rock_Slate"
    },
    {
      "x": -7,
      "y": 29,
      "z": 12,
      "name": "Rock_Slate"
    },
    {
      "x": -7,
      "y": 30,
      "z": 12,
      "name": "Rock_Slate"
    },
    {
      "x": -7,
      "y": 31,
      "z": 12,
      "name": "Rock_Slate"
    },
    {
      "x": -7,
      "y": 32,
      "z": 12,
      "name": "Rock_Slate"
    },
    {
      "x": -6,
      "y": 29,
      "z": -12,
      "name": "Rock_Slate"
    },
    {
      "x": -6,
      "y": 30,
      "z": -12,
      "name": "Rock_Slate"
    },
    {
      "x": -6,
      "y": 31,
      "z": -12,
      "name": "Rock_Slate"
    },
    {
      "x": -6,
      "y": 32,
      "z": -12,
      "name": "Rock_Slate"
    },
    {
      "x": -6,
      "y": 7,
      "z": -6,
      "name": "Rock_Slate_Cobble"
    },
    {
      "x": -6,
      "y": 7,
      "z": -5,
      "name": "Rock_Slate_Cobble"
    },
    {
      "x": -6,
      "y": 7,
      "z": -4,
      "name": "Rock_Slate_Cobble"
    },
    {
      "x": -6,
      "y": 7,
      "z": -3,
      "name": "Rock_Slate_Cobble"
    },
    {
      "x": -6,
      "y": 7,
      "z": -2,
      "name": "Rock_Slate_Cobble"
    },
    {
      "x": -6,
      "y": 7,
      "z": -1,
      "name": "Rock_Slate_Cobble"
    },
    {
      "x": -6,
      "y": 7,
      "z": 0,
      "name": "Rock_Slate_Cobble"
    },
    {
      "x": -6,
      "y": 7,
      "z": 1,
      "name": "Rock_Slate_Cobble"
    },
    {
      "x": -6,
      "y": 7,
      "z": 2,
      "name": "Rock_Slate_Cobble"
    },
    {
      "x": -6,
      "y": 7,
      "z": 3,
      "name": "Rock_Slate_Cobble"
    },
    {
      "x": -6,
      "y": 11,
      "z": 12,
      "name": "Rock_Slate"
    },
    {
      "x": -6,
      "y": 12,
      "z": 12,
      "name": "Rock_Slate"
    },
    {
      "x": -6,
      "y": 13,
      "z": 12,
      "name": "Rock_Slate"
    },
    {
      "x": -6,
      "y": 14,
      "z": 12,
      "name": "Rock_Slate"
    },
    {
      "x": -6,
      "y": 15,
      "z": 12,
      "name": "Rock_Slate"
    },
    {
      "x": -6,
      "y": 16,
      "z": 12,
      "name": "Rock_Slate"
    },
    {
      "x": -6,
      "y": 17,
      "z": 12,
      "name": "Rock_Slate"
    },
    {
      "x": -6,
      "y": 18,
      "z": 12,
      "name": "Rock_Slate"
    },
    {
      "x": -6,
      "y": 19,
      "z": 12,
      "name": "Rock_Slate"
    },
    {
      "x": -6,
      "y": 20,
      "z": 12,
      "name": "Rock_Slate"
    },
    {
      "x": -6,
      "y": 21,
      "z": 12,
      "name": "Rock_Slate"
    },
    {
      "x": -6,
      "y": 22,
      "z": 12,
      "name": "Rock_Slate"
    },
    {
      "x": -6,
      "y": 23,
      "z": 12,
      "name": "Rock_Slate"
    },
    {
      "x": -6,
      "y": 24,
      "z": 12,
      "name": "Rock_Slate"
    },
    {
      "x": -6,
      "y": 25,
      "z": 12,
      "name": "Rock_Slate"
    },
    {
      "x": -6,
      "y": 26,
      "z": 12,
      "name": "Rock_Slate"
    },
    {
      "x": -6,
      "y": 27,
      "z": 12,
      "name": "Rock_Slate"
    },
    {
      "x": -6,
      "y": 28,
      "z": 12,
      "name": "Rock_Slate"
    },
    {
      "x": -6,
      "y": 29,
      "z": 12,
      "name": "Rock_Slate"
    },
    {
      "x": -6,
      "y": 30,
      "z": 12,
      "name": "Rock_Slate"
    },
    {
      "x": -6,
      "y": 31,
      "z": 12,
      "name": "Rock_Slate"
    },
    {
      "x": -6,
      "y": 32,
      "z": 12,
      "name": "Rock_Slate"
    },
    {
      "x": -5,
      "y": 7,
      "z": -7,
      "name": "Rock_Slate_Cobble"
    },
    {
      "x": -5,
      "y": 7,
      "z": -6,
      "name": "Rock_Slate_Cobble"
    },
    {
      "x": -5,
      "y": 7,
      "z": -5,
      "name": "Rock_Slate_Cobble"
    },
    {
      "x": -5,
      "y": 7,
      "z": -4,
      "name": "Rock_Slate_Cobble"
    },
    {
      "x": -5,
      "y": 7,
      "z": -3,
      "name": "Rock_Slate_Cobble"
    },
    {
      "x": -5,
      "y": 7,
      "z": -2,
      "name": "Rock_Slate_Cobble"
    },
    {
      "x": -5,
      "y": 7,
      "z": -1,
      "name": "Rock_Slate_Cobble"
    },
    {
      "x": -5,
      "y": 7,
      "z": 0,
      "name": "Rock_Slate_Cobble"
    },
    {
      "x": -5,
      "y": 7,
      "z": 1,
      "name": "Rock_Slate_Cobble"
    },
    {
      "x": -5,
      "y": 7,
      "z": 2,
      "name": "Rock_Slate_Cobble"
    },
    {
      "x": -5,
      "y": 7,
      "z": 3,
      "name": "Rock_Slate_Cobble"
    },
    {
      "x": -5,
      "y": 7,
      "z": 4,
      "name": "Rock_Slate_Cobble"
    },
    {
      "x": -5,
      "y": 28,
      "z": 12,
      "name": "Rock_Slate"
    },
    {
      "x": -5,
      "y": 29,
      "z": 12,
      "name": "Rock_Slate"
    },
    {
      "x": -5,
      "y": 30,
      "z": 12,
      "name": "Rock_Slate"
    },
    {
      "x": -5,
      "y": 31,
      "z": 12,
      "name": "Rock_Slate"
    },
    {
      "x": -4,
      "y": 29,
      "z": -12,
      "name": "Rock_Slate"
    },
    {
      "x": -4,
      "y": 30,
      "z": -12,
      "name": "Rock_Slate"
    },
    {
      "x": -4,
      "y": 31,
      "z": -12,
      "name": "Rock_Slate"
    },
    {
      "x": -4,
      "y": 32,
      "z": -12,
      "name": "Rock_Slate"
    },
    {
      "x": -4,
      "y": 7,
      "z": -7,
      "name": "Rock_Slate_Cobble"
    },
    {
      "x": -4,
      "y": 7,
      "z": -6,
      "name": "Rock_Slate_Cobble"
    },
    {
      "x": -4,
      "y": 7,
      "z": -5,
      "name": "Rock_Slate_Cobble"
    },
    {
      "x": -4,
      "y": 4,
      "z": -4,
      "name": "Rock_Slate_Cobble"
    },
    {
      "x": -4,
      "y": 5,
      "z": -4,
      "name": "Rock_Slate_Cobble"
    },
    {
      "x": -4,
      "y": 6,
      "z": -4,
      "name": "Rock_Slate_Cobble"
    },
    {
      "x": -4,
      "y": 7,
      "z": -4,
      "name": "Rock_Slate_Cobble"
    },
    {
      "x": -4,
      "y": 7,
      "z": -3,
      "name": "Rock_Slate_Cobble"
    },
    {
      "x": -4,
      "y": 7,
      "z": -2,
      "name": "Rock_Slate_Cobble"
    },
    {
      "x": -4,
      "y": 6,
      "z": -1,
      "name": "Rock_Slate_Cobble"
    },
    {
      "x": -4,
      "y": 7,
      "z": -1,
      "name": "Rock_Slate_Cobble"
    },
    {
      "x": -4,
      "y": 7,
      "z": 0,
      "name": "Rock_Slate_Cobble"
    },
    {
      "x": -4,
      "y": 7,
      "z": 1,
      "name": "Rock_Slate_Cobble"
    },
    {
      "x": -4,
      "y": 7,
      "z": 2,
      "name": "Rock_Slate_Cobble"
    },
    {
      "x": -4,
      "y": 7,
      "z": 3,
      "name": "Rock_Slate_Cobble"
    },
    {
      "x": -4,
      "y": 7,
      "z": 4,
      "name": "Rock_Slate_Cobble"
    },
    {
      "x": -4,
      "y": 29,
      "z": 12,
      "name": "Rock_Slate"
    },
    {
      "x": -4,
      "y": 31,
      "z": 12,
      "name": "Rock_Slate"
    },
    {
      "x": -4,
      "y": 32,
      "z": 12,
      "name": "Rock_Slate"
    },
    {
      "x": -3,
      "y": 8,
      "z": -12,
      "name": "Rock_Slate"
    },
    {
      "x": -3,
      "y": 9,
      "z": -12,
      "name": "Rock_Slate"
    },
    {
      "x": -3,
      "y": 10,
      "z": -12,
      "name": "Rock_Slate"
    },
    {
      "x": -3,
      "y": 11,
      "z": -12,
      "name": "Rock_Slate"
    },
    {
      "x": -3,
      "y": 12,
      "z": -12,
      "name": "Rock_Slate"
    },
    {
      "x": -3,
      "y": 13,
      "z": -12,
      "name": "Rock_Slate"
    },
    {
      "x": -3,
      "y": 14,
      "z": -12,
      "name": "Rock_Slate"
    },
    {
      "x": -3,
      "y": 15,
      "z": -12,
      "name": "Rock_Slate"
    },
    {
      "x": -3,
      "y": 16,
      "z": -12,
      "name": "Rock_Slate"
    },
    {
      "x": -3,
      "y": 17,
      "z": -12,
      "name": "Rock_Slate"
    },
    {
      "x": -3,
      "y": 18,
      "z": -12,
      "name": "Rock_Slate"
    },
    {
      "x": -3,
      "y": 19,
      "z": -12,
      "name": "Rock_Slate"
    },
    {
      "x": -3,
      "y": 20,
      "z": -12,
      "name": "Rock_Slate"
    },
    {
      "x": -3,
      "y": 21,
      "z": -12,
      "name": "Rock_Slate"
    },
    {
      "x": -3,
      "y": 22,
      "z": -12,
      "name": "Rock_Slate"
    },
    {
      "x": -3,
      "y": 23,
      "z": -12,
      "name": "Rock_Slate"
    },
    {
      "x": -3,
      "y": 24,
      "z": -12,
      "name": "Rock_Slate"
    },
    {
      "x": -3,
      "y": 25,
      "z": -12,
      "name": "Rock_Slate"
    },
    {
      "x": -3,
      "y": 26,
      "z": -12,
      "name": "Rock_Slate"
    },
    {
      "x": -3,
      "y": 27,
      "z": -12,
      "name": "Rock_Slate"
    },
    {
      "x": -3,
      "y": 28,
      "z": -12,
      "name": "Rock_Slate"
    },
    {
      "x": -3,
      "y": 29,
      "z": -12,
      "name": "Rock_Slate"
    },
    {
      "x": -3,
      "y": 30,
      "z": -12,
      "name": "Rock_Slate"
    },
    {
      "x": -3,
      "y": 31,
      "z": -12,
      "name": "Rock_Slate"
    },
    {
      "x": -3,
      "y": 32,
      "z": -12,
      "name": "Rock_Slate"
    },
    {
      "x": -3,
      "y": 7,
      "z": -7,
      "name": "Rock_Slate_Cobble"
    },
    {
      "x": -3,
      "y": 7,
      "z": -6,
      "name": "Rock_Slate_Cobble"
    },
    {
      "x": -3,
      "y": 7,
      "z": -5,
      "name": "Rock_Slate_Cobble"
    },
    {
      "x": -3,
      "y": 7,
      "z": -4,
      "name": "Rock_Slate_Cobble"
    },
    {
      "x": -3,
      "y": 7,
      "z": -3,
      "name": "Rock_Slate_Cobble"
    },
    {
      "x": -3,
      "y": 7,
      "z": -2,
      "name": "Rock_Slate_Cobble"
    },
    {
      "x": -3,
      "y": 7,
      "z": -1,
      "name": "Rock_Slate_Cobble"
    },
    {
      "x": -3,
      "y": 7,
      "z": 0,
      "name": "Rock_Slate_Cobble"
    },
    {
      "x": -3,
      "y": 3,
      "z": 1,
      "name": "Rock_Slate_Cobble"
    },
    {
      "x": -3,
      "y": 4,
      "z": 1,
      "name": "Rock_Slate_Cobble"
    },
    {
      "x": -3,
      "y": 5,
      "z": 1,
      "name": "Rock_Slate_Cobble"
    },
    {
      "x": -3,
      "y": 6,
      "z": 1,
      "name": "Rock_Slate_Cobble"
    },
    {
      "x": -3,
      "y": 7,
      "z": 1,
      "name": "Rock_Slate_Cobble"
    },
    {
      "x": -3,
      "y": 7,
      "z": 2,
      "name": "Rock_Slate_Cobble"
    },
    {
      "x": -3,
      "y": 7,
      "z": 3,
      "name": "Rock_Slate_Cobble"
    },
    {
      "x": -3,
      "y": 7,
      "z": 4,
      "name": "Rock_Slate_Cobble"
    },
    {
      "x": -3,
      "y": 32,
      "z": 11,
      "name": "Ore_Server"
    },
    {
      "x": -3,
      "y": 29,
      "z": 12,
      "name": "Rock_Slate"
    },
    {
      "x": -3,
      "y": 30,
      "z": 12,
      "name": "Rock_Slate"
    },
    {
      "x": -3,
      "y": 31,
      "z": 12,
      "name": "Rock_Slate"
    },
    {
      "x": -3,
      "y": 32,
      "z": 12,
      "name": "Rock_Slate"
    },
    {
      "x": -2,
      "y": 8,
      "z": -12,
      "name": "Rock_Slate"
    },
    {
      "x": -2,
      "y": 9,
      "z": -12,
      "name": "Rock_Slate"
    },
    {
      "x": -2,
      "y": 10,
      "z": -12,
      "name": "Rock_Slate"
    },
    {
      "x": -2,
      "y": 11,
      "z": -12,
      "name": "Rock_Slate"
    },
    {
      "x": -2,
      "y": 12,
      "z": -12,
      "name": "Rock_Slate"
    },
    {
      "x": -2,
      "y": 13,
      "z": -12,
      "name": "Rock_Slate"
    },
    {
      "x": -2,
      "y": 14,
      "z": -12,
      "name": "Rock_Slate"
    },
    {
      "x": -2,
      "y": 15,
      "z": -12,
      "name": "Rock_Slate"
    },
    {
      "x": -2,
      "y": 16,
      "z": -12,
      "name": "Rock_Slate"
    },
    {
      "x": -2,
      "y": 17,
      "z": -12,
      "name": "Rock_Slate"
    },
    {
      "x": -2,
      "y": 18,
      "z": -12,
      "name": "Rock_Slate"
    },
    {
      "x": -2,
      "y": 19,
      "z": -12,
      "name": "Rock_Slate"
    },
    {
      "x": -2,
      "y": 20,
      "z": -12,
      "name": "Rock_Slate"
    },
    {
      "x": -2,
      "y": 21,
      "z": -12,
      "name": "Rock_Slate"
    },
    {
      "x": -2,
      "y": 22,
      "z": -12,
      "name": "Rock_Slate"
    },
    {
      "x": -2,
      "y": 23,
      "z": -12,
      "name": "Rock_Slate"
    },
    {
      "x": -2,
      "y": 24,
      "z": -12,
      "name": "Rock_Slate"
    },
    {
      "x": -2,
      "y": 25,
      "z": -12,
      "name": "Rock_Slate"
    },
    {
      "x": -2,
      "y": 26,
      "z": -12,
      "name": "Rock_Slate"
    },
    {
      "x": -2,
      "y": 27,
      "z": -12,
      "name": "Rock_Slate"
    },
    {
      "x": -2,
      "y": 28,
      "z": -12,
      "name": "Rock_Slate"
    },
    {
      "x": -2,
      "y": 29,
      "z": -12,
      "name": "Rock_Slate"
    },
    {
      "x": -2,
      "y": 30,
      "z": -12,
      "name": "Rock_Slate"
    },
    {
      "x": -2,
      "y": 31,
      "z": -12,
      "name": "Rock_Slate"
    },
    {
      "x": -2,
      "y": 32,
      "z": -12,
      "name": "Rock_Slate"
    },
    {
      "x": -2,
      "y": 7,
      "z": -7,
      "name": "Rock_Slate_Cobble"
    },
    {
      "x": -2,
      "y": 6,
      "z": -6,
      "name": "Rock_Slate_Cobble"
    },
    {
      "x": -2,
      "y": 7,
      "z": -6,
      "name": "Rock_Slate_Cobble"
    },
    {
      "x": -2,
      "y": 7,
      "z": -5,
      "name": "Rock_Slate_Cobble"
    },
    {
      "x": -2,
      "y": 7,
      "z": -4,
      "name": "Rock_Slate_Cobble"
    },
    {
      "x": -2,
      "y": 7,
      "z": -3,
      "name": "Rock_Slate_Cobble"
    },
    {
      "x": -2,
      "y": 7,
      "z": -2,
      "name": "Rock_Slate_Cobble"
    },
    {
      "x": -2,
      "y": 7,
      "z": -1,
      "name": "Rock_Slate_Cobble"
    },
    {
      "x": -2,
      "y": 7,
      "z": 0,
      "name": "Rock_Slate_Cobble"
    },
    {
      "x": -2,
      "y": 7,
      "z": 1,
      "name": "Rock_Slate_Cobble"
    },
    {
      "x": -2,
      "y": 7,
      "z": 2,
      "name": "Rock_Slate_Cobble"
    },
    {
      "x": -2,
      "y": 7,
      "z": 3,
      "name": "Rock_Slate_Cobble"
    },
    {
      "x": -2,
      "y": 7,
      "z": 4,
      "name": "Rock_Slate_Cobble"
    },
    {
      "x": -2,
      "y": 8,
      "z": 12,
      "name": "Rock_Slate"
    },
    {
      "x": -2,
      "y": 9,
      "z": 12,
      "name": "Rock_Slate"
    },
    {
      "x": -2,
      "y": 10,
      "z": 12,
      "name": "Rock_Slate"
    },
    {
      "x": -2,
      "y": 11,
      "z": 12,
      "name": "Rock_Slate"
    },
    {
      "x": -2,
      "y": 12,
      "z": 12,
      "name": "Rock_Slate"
    },
    {
      "x": -2,
      "y": 13,
      "z": 12,
      "name": "Rock_Slate"
    },
    {
      "x": -2,
      "y": 14,
      "z": 12,
      "name": "Rock_Slate"
    },
    {
      "x": -2,
      "y": 15,
      "z": 12,
      "name": "Rock_Slate"
    },
    {
      "x": -2,
      "y": 16,
      "z": 12,
      "name": "Rock_Slate"
    },
    {
      "x": -2,
      "y": 17,
      "z": 12,
      "name": "Rock_Slate"
    },
    {
      "x": -2,
      "y": 18,
      "z": 12,
      "name": "Rock_Slate"
    },
    {
      "x": -2,
      "y": 19,
      "z": 12,
      "name": "Rock_Slate"
    },
    {
      "x": -2,
      "y": 20,
      "z": 12,
      "name": "Rock_Slate"
    },
    {
      "x": -2,
      "y": 21,
      "z": 12,
      "name": "Rock_Slate"
    },
    {
      "x": -2,
      "y": 22,
      "z": 12,
      "name": "Rock_Slate"
    },
    {
      "x": -2,
      "y": 23,
      "z": 12,
      "name": "Rock_Slate"
    },
    {
      "x": -2,
      "y": 24,
      "z": 12,
      "name": "Rock_Slate"
    },
    {
      "x": -2,
      "y": 25,
      "z": 12,
      "name": "Rock_Slate"
    },
    {
      "x": -2,
      "y": 26,
      "z": 12,
      "name": "Rock_Slate"
    },
    {
      "x": -2,
      "y": 27,
      "z": 12,
      "name": "Rock_Slate"
    },
    {
      "x": -2,
      "y": 28,
      "z": 12,
      "name": "Rock_Slate"
    },
    {
      "x": -2,
      "y": 29,
      "z": 12,
      "name": "Rock_Slate"
    },
    {
      "x": -2,
      "y": 30,
      "z": 12,
      "name": "Rock_Slate"
    },
    {
      "x": -2,
      "y": 31,
      "z": 12,
      "name": "Rock_Slate"
    },
    {
      "x": -2,
      "y": 32,
      "z": 12,
      "name": "Rock_Slate"
    },
    {
      "x": -1,
      "y": 25,
      "z": -12,
      "name": "Rock_Slate"
    },
    {
      "x": -1,
      "y": 26,
      "z": -12,
      "name": "Rock_Slate"
    },
    {
      "x": -1,
      "y": 27,
      "z": -12,
      "name": "Rock_Slate"
    },
    {
      "x": -1,
      "y": 28,
      "z": -12,
      "name": "Rock_Slate"
    },
    {
      "x": -1,
      "y": 29,
      "z": -12,
      "name": "Rock_Slate"
    },
    {
      "x": -1,
      "y": 30,
      "z": -12,
      "name": "Rock_Slate"
    },
    {
      "x": -1,
      "y": 29,
      "z": -11,
      "name": "Ore_Server"
    },
    {
      "x": -1,
      "y": 7,
      "z": -7,
      "name": "Rock_Slate_Cobble"
    },
    {
      "x": -1,
      "y": 7,
      "z": -6,
      "name": "Rock_Slate_Cobble"
    },
    {
      "x": -1,
      "y": 7,
      "z": -5,
      "name": "Rock_Slate_Cobble"
    },
    {
      "x": -1,
      "y": 7,
      "z": -4,
      "name": "Rock_Slate_Cobble"
    },
    {
      "x": -1,
      "y": 7,
      "z": -3,
      "name": "Rock_Slate_Cobble"
    },
    {
      "x": -1,
      "y": 0,
      "z": -2,
      "name": "Rock_Slate_Cobble"
    },
    {
      "x": -1,
      "y": 1,
      "z": -2,
      "name": "Rock_Slate_Cobble"
    },
    {
      "x": -1,
      "y": 2,
      "z": -2,
      "name": "Rock_Slate_Cobble"
    },
    {
      "x": -1,
      "y": 3,
      "z": -2,
      "name": "Rock_Slate_Cobble"
    },
    {
      "x": -1,
      "y": 4,
      "z": -2,
      "name": "Rock_Slate_Cobble"
    },
    {
      "x": -1,
      "y": 5,
      "z": -2,
      "name": "Rock_Slate_Cobble"
    },
    {
      "x": -1,
      "y": 6,
      "z": -2,
      "name": "Rock_Slate_Cobble"
    },
    {
      "x": -1,
      "y": 7,
      "z": -2,
      "name": "Rock_Slate_Cobble"
    },
    {
      "x": -1,
      "y": 7,
      "z": -1,
      "name": "Rock_Slate_Cobble"
    },
    {
      "x": -1,
      "y": 7,
      "z": 0,
      "name": "Rock_Slate_Cobble"
    },
    {
      "x": -1,
      "y": 6,
      "z": 1,
      "name": "Rock_Slate_Cobble"
    },
    {
      "x": -1,
      "y": 7,
      "z": 1,
      "name": "Rock_Slate_Cobble"
    },
    {
      "x": -1,
      "y": 7,
      "z": 2,
      "name": "Rock_Slate_Cobble"
    },
    {
      "x": -1,
      "y": 7,
      "z": 3,
      "name": "Rock_Slate_Cobble"
    },
    {
      "x": -1,
      "y": 7,
      "z": 4,
      "name": "Rock_Slate_Cobble"
    },
    {
      "x": -1,
      "y": 25,
      "z": 12,
      "name": "Rock_Slate"
    },
    {
      "x": -1,
      "y": 26,
      "z": 12,
      "name": "Rock_Slate"
    },
    {
      "x": -1,
      "y": 27,
      "z": 12,
      "name": "Rock_Slate"
    },
    {
      "x": -1,
      "y": 28,
      "z": 12,
      "name": "Rock_Slate"
    },
    {
      "x": -1,
      "y": 29,
      "z": 12,
      "name": "Rock_Slate"
    },
    {
      "x": -1,
      "y": 30,
      "z": 12,
      "name": "Rock_Slate"
    },
    {
      "x": -1,
      "y": 31,
      "z": 12,
      "name": "Rock_Slate"
    },
    {
      "x": -1,
      "y": 32,
      "z": 12,
      "name": "Rock_Slate"
    },
    {
      "x": 0,
      "y": 28,
      "z": -12,
      "name": "Rock_Slate"
    },
    {
      "x": 0,
      "y": 29,
      "z": -12,
      "name": "Rock_Slate"
    },
    {
      "x": 0,
      "y": 30,
      "z": -12,
      "name": "Rock_Slate"
    },
    {
      "x": 0,
      "y": 31,
      "z": -12,
      "name": "Rock_Slate"
    },
    {
      "x": 0,
      "y": 32,
      "z": -12,
      "name": "Rock_Slate"
    },
    {
      "x": 0,
      "y": 7,
      "z": -7,
      "name": "Rock_Slate_Cobble"
    },
    {
      "x": 0,
      "y": 7,
      "z": -6,
      "name": "Rock_Slate_Cobble"
    },
    {
      "x": 0,
      "y": 7,
      "z": -5,
      "name": "Rock_Slate_Cobble"
    },
    {
      "x": 0,
      "y": 4,
      "z": -4,
      "name": "Rock_Slate_Cobble"
    },
    {
      "x": 0,
      "y": 5,
      "z": -4,
      "name": "Rock_Slate_Cobble"
    },
    {
      "x": 0,
      "y": 6,
      "z": -4,
      "name": "Rock_Slate_Cobble"
    },
    {
      "x": 0,
      "y": 7,
      "z": -4,
      "name": "Rock_Slate_Cobble"
    },
    {
      "x": 0,
      "y": 7,
      "z": -3,
      "name": "Rock_Slate_Cobble"
    },
    {
      "x": 0,
      "y": 7,
      "z": -2,
      "name": "Rock_Slate_Cobble"
    },
    {
      "x": 0,
      "y": 7,
      "z": -1,
      "name": "Rock_Slate_Cobble"
    },
    {
      "x": 0,
      "y": 7,
      "z": 0,
      "name": "Rock_Slate_Cobble"
    },
    {
      "x": 0,
      "y": 7,
      "z": 1,
      "name": "Rock_Slate_Cobble"
    },
    {
      "x": 0,
      "y": 7,
      "z": 2,
      "name": "Rock_Slate_Cobble"
    },
    {
      "x": 0,
      "y": 7,
      "z": 3,
      "name": "Rock_Slate_Cobble"
    },
    {
      "x": 0,
      "y": 7,
      "z": 4,
      "name": "Rock_Slate_Cobble"
    },
    {
      "x": 0,
      "y": 26,
      "z": 12,
      "name": "Rock_Slate"
    },
    {
      "x": 0,
      "y": 27,
      "z": 12,
      "name": "Rock_Slate"
    },
    {
      "x": 0,
      "y": 28,
      "z": 12,
      "name": "Rock_Slate"
    },
    {
      "x": 0,
      "y": 29,
      "z": 12,
      "name": "Rock_Slate"
    },
    {
      "x": 0,
      "y": 30,
      "z": 12,
      "name": "Rock_Slate"
    },
    {
      "x": 0,
      "y": 31,
      "z": 12,
      "name": "Rock_Slate"
    },
    {
      "x": 0,
      "y": 32,
      "z": 12,
      "name": "Rock_Slate"
    },
    {
      "x": 1,
      "y": 27,
      "z": -12,
      "name": "Rock_Slate"
    },
    {
      "x": 1,
      "y": 28,
      "z": -12,
      "name": "Rock_Slate"
    },
    {
      "x": 1,
      "y": 29,
      "z": -12,
      "name": "Rock_Slate"
    },
    {
      "x": 1,
      "y": 30,
      "z": -12,
      "name": "Rock_Slate"
    },
    {
      "x": 1,
      "y": 31,
      "z": -12,
      "name": "Rock_Slate"
    },
    {
      "x": 1,
      "y": 30,
      "z": -11,
      "name": "Ore_Server"
    },
    {
      "x": 1,
      "y": 7,
      "z": -7,
      "name": "Rock_Slate_Cobble"
    },
    {
      "x": 1,
      "y": 7,
      "z": -6,
      "name": "Rock_Slate_Cobble"
    },
    {
      "x": 1,
      "y": 7,
      "z": -5,
      "name": "Rock_Slate_Cobble"
    },
    {
      "x": 1,
      "y": 7,
      "z": -4,
      "name": "Rock_Slate_Cobble"
    },
    {
      "x": 1,
      "y": 7,
      "z": -3,
      "name": "Rock_Slate_Cobble"
    },
    {
      "x": 1,
      "y": 7,
      "z": -2,
      "name": "Rock_Slate_Cobble"
    },
    {
      "x": 1,
      "y": 7,
      "z": -1,
      "name": "Rock_Slate_Cobble"
    },
    {
      "x": 1,
      "y": 7,
      "z": 0,
      "name": "Rock_Slate_Cobble"
    },
    {
      "x": 1,
      "y": 4,
      "z": 1,
      "name": "Rock_Slate_Cobble"
    },
    {
      "x": 1,
      "y": 5,
      "z": 1,
      "name": "Rock_Slate_Cobble"
    },
    {
      "x": 1,
      "y": 6,
      "z": 1,
      "name": "Rock_Slate_Cobble"
    },
    {
      "x": 1,
      "y": 7,
      "z": 1,
      "name": "Rock_Slate_Cobble"
    },
    {
      "x": 1,
      "y": 7,
      "z": 2,
      "name": "Rock_Slate_Cobble"
    },
    {
      "x": 1,
      "y": 7,
      "z": 3,
      "name": "Rock_Slate_Cobble"
    },
    {
      "x": 1,
      "y": 7,
      "z": 4,
      "name": "Rock_Slate_Cobble"
    },
    {
      "x": 1,
      "y": 30,
      "z": 11,
      "name": "Ore_Server"
    },
    {
      "x": 1,
      "y": 27,
      "z": 12,
      "name": "Rock_Slate"
    },
    {
      "x": 1,
      "y": 28,
      "z": 12,
      "name": "Rock_Slate"
    },
    {
      "x": 1,
      "y": 29,
      "z": 12,
      "name": "Rock_Slate"
    },
    {
      "x": 1,
      "y": 30,
      "z": 12,
      "name": "Rock_Slate"
    },
    {
      "x": 1,
      "y": 31,
      "z": 12,
      "name": "Rock_Slate"
    },
    {
      "x": 2,
      "y": 10,
      "z": -12,
      "name": "Rock_Slate"
    },
    {
      "x": 2,
      "y": 11,
      "z": -12,
      "name": "Rock_Slate"
    },
    {
      "x": 2,
      "y": 12,
      "z": -12,
      "name": "Rock_Slate"
    },
    {
      "x": 2,
      "y": 13,
      "z": -12,
      "name": "Rock_Slate"
    },
    {
      "x": 2,
      "y": 14,
      "z": -12,
      "name": "Rock_Slate"
    },
    {
      "x": 2,
      "y": 15,
      "z": -12,
      "name": "Rock_Slate"
    },
    {
      "x": 2,
      "y": 16,
      "z": -12,
      "name": "Rock_Slate"
    },
    {
      "x": 2,
      "y": 17,
      "z": -12,
      "name": "Rock_Slate"
    },
    {
      "x": 2,
      "y": 18,
      "z": -12,
      "name": "Rock_Slate"
    },
    {
      "x": 2,
      "y": 19,
      "z": -12,
      "name": "Rock_Slate"
    },
    {
      "x": 2,
      "y": 20,
      "z": -12,
      "name": "Rock_Slate"
    },
    {
      "x": 2,
      "y": 21,
      "z": -12,
      "name": "Rock_Slate"
    },
    {
      "x": 2,
      "y": 22,
      "z": -12,
      "name": "Rock_Slate"
    },
    {
      "x": 2,
      "y": 23,
      "z": -12,
      "name": "Rock_Slate"
    },
    {
      "x": 2,
      "y": 24,
      "z": -12,
      "name": "Rock_Slate"
    },
    {
      "x": 2,
      "y": 25,
      "z": -12,
      "name": "Rock_Slate"
    },
    {
      "x": 2,
      "y": 26,
      "z": -12,
      "name": "Rock_Slate"
    },
    {
      "x": 2,
      "y": 27,
      "z": -12,
      "name": "Rock_Slate"
    },
    {
      "x": 2,
      "y": 28,
      "z": -12,
      "name": "Rock_Slate"
    },
    {
      "x": 2,
      "y": 29,
      "z": -12,
      "name": "Rock_Slate"
    },
    {
      "x": 2,
      "y": 30,
      "z": -12,
      "name": "Rock_Slate"
    },
    {
      "x": 2,
      "y": 31,
      "z": -12,
      "name": "Rock_Slate"
    },
    {
      "x": 2,
      "y": 7,
      "z": -7,
      "name": "Rock_Slate_Cobble"
    },
    {
      "x": 2,
      "y": 7,
      "z": -6,
      "name": "Rock_Slate_Cobble"
    },
    {
      "x": 2,
      "y": 7,
      "z": -5,
      "name": "Rock_Slate_Cobble"
    },
    {
      "x": 2,
      "y": 7,
      "z": -4,
      "name": "Rock_Slate_Cobble"
    },
    {
      "x": 2,
      "y": 3,
      "z": -3,
      "name": "Rock_Slate_Cobble"
    },
    {
      "x": 2,
      "y": 4,
      "z": -3,
      "name": "Rock_Slate_Cobble"
    },
    {
      "x": 2,
      "y": 5,
      "z": -3,
      "name": "Rock_Slate_Cobble"
    },
    {
      "x": 2,
      "y": 6,
      "z": -3,
      "name": "Rock_Slate_Cobble"
    },
    {
      "x": 2,
      "y": 7,
      "z": -3,
      "name": "Rock_Slate_Cobble"
    },
    {
      "x": 2,
      "y": 7,
      "z": -2,
      "name": "Rock_Slate_Cobble"
    },
    {
      "x": 2,
      "y": 7,
      "z": -1,
      "name": "Rock_Slate_Cobble"
    },
    {
      "x": 2,
      "y": 7,
      "z": 0,
      "name": "Rock_Slate_Cobble"
    },
    {
      "x": 2,
      "y": 7,
      "z": 1,
      "name": "Rock_Slate_Cobble"
    },
    {
      "x": 2,
      "y": 7,
      "z": 2,
      "name": "Rock_Slate_Cobble"
    },
    {
      "x": 2,
      "y": 7,
      "z": 3,
      "name": "Rock_Slate_Cobble"
    },
    {
      "x": 2,
      "y": 7,
      "z": 4,
      "name": "Rock_Slate_Cobble"
    },
    {
      "x": 2,
      "y": 11,
      "z": 12,
      "name": "Rock_Slate"
    },
    {
      "x": 2,
      "y": 12,
      "z": 12,
      "name": "Rock_Slate"
    },
    {
      "x": 2,
      "y": 13,
      "z": 12,
      "name": "Rock_Slate"
    },
    {
      "x": 2,
      "y": 14,
      "z": 12,
      "name": "Rock_Slate"
    },
    {
      "x": 2,
      "y": 15,
      "z": 12,
      "name": "Rock_Slate"
    },
    {
      "x": 2,
      "y": 16,
      "z": 12,
      "name": "Rock_Slate"
    },
    {
      "x": 2,
      "y": 17,
      "z": 12,
      "name": "Rock_Slate"
    },
    {
      "x": 2,
      "y": 18,
      "z": 12,
      "name": "Rock_Slate"
    },
    {
      "x": 2,
      "y": 19,
      "z": 12,
      "name": "Rock_Slate"
    },
    {
      "x": 2,
      "y": 20,
      "z": 12,
      "name": "Rock_Slate"
    },
    {
      "x": 2,
      "y": 21,
      "z": 12,
      "name": "Rock_Slate"
    },
    {
      "x": 2,
      "y": 22,
      "z": 12,
      "name": "Rock_Slate"
    },
    {
      "x": 2,
      "y": 23,
      "z": 12,
      "name": "Rock_Slate"
    },
    {
      "x": 2,
      "y": 24,
      "z": 12,
      "name": "Rock_Slate"
    },
    {
      "x": 2,
      "y": 25,
      "z": 12,
      "name": "Rock_Slate"
    },
    {
      "x": 2,
      "y": 26,
      "z": 12,
      "name": "Rock_Slate"
    },
    {
      "x": 2,
      "y": 27,
      "z": 12,
      "name": "Rock_Slate"
    },
    {
      "x": 2,
      "y": 28,
      "z": 12,
      "name": "Rock_Slate"
    },
    {
      "x": 2,
      "y": 29,
      "z": 12,
      "name": "Rock_Slate"
    },
    {
      "x": 2,
      "y": 30,
      "z": 12,
      "name": "Rock_Slate"
    },
    {
      "x": 2,
      "y": 31,
      "z": 12,
      "name": "Rock_Slate"
    },
    {
      "x": 2,
      "y": 32,
      "z": 12,
      "name": "Rock_Slate"
    },
    {
      "x": 3,
      "y": 29,
      "z": -12,
      "name": "Rock_Slate"
    },
    {
      "x": 3,
      "y": 30,
      "z": -12,
      "name": "Rock_Slate"
    },
    {
      "x": 3,
      "y": 31,
      "z": -12,
      "name": "Rock_Slate"
    },
    {
      "x": 3,
      "y": 7,
      "z": -7,
      "name": "Rock_Slate_Cobble"
    },
    {
      "x": 3,
      "y": 7,
      "z": -6,
      "name": "Rock_Slate_Cobble"
    },
    {
      "x": 3,
      "y": 7,
      "z": -5,
      "name": "Rock_Slate_Cobble"
    },
    {
      "x": 3,
      "y": 7,
      "z": -4,
      "name": "Rock_Slate_Cobble"
    },
    {
      "x": 3,
      "y": 7,
      "z": -3,
      "name": "Rock_Slate_Cobble"
    },
    {
      "x": 3,
      "y": 7,
      "z": -2,
      "name": "Rock_Slate_Cobble"
    },
    {
      "x": 3,
      "y": 7,
      "z": -1,
      "name": "Rock_Slate_Cobble"
    },
    {
      "x": 3,
      "y": 7,
      "z": 0,
      "name": "Rock_Slate_Cobble"
    },
    {
      "x": 3,
      "y": 7,
      "z": 1,
      "name": "Rock_Slate_Cobble"
    },
    {
      "x": 3,
      "y": 7,
      "z": 2,
      "name": "Rock_Slate_Cobble"
    },
    {
      "x": 3,
      "y": 7,
      "z": 3,
      "name": "Rock_Slate_Cobble"
    },
    {
      "x": 3,
      "y": 7,
      "z": 4,
      "name": "Rock_Slate_Cobble"
    },
    {
      "x": 3,
      "y": 30,
      "z": 12,
      "name": "Rock_Slate"
    },
    {
      "x": 3,
      "y": 31,
      "z": 12,
      "name": "Rock_Slate"
    },
    {
      "x": 3,
      "y": 32,
      "z": 12,
      "name": "Rock_Slate"
    },
    {
      "x": 4,
      "y": 29,
      "z": -12,
      "name": "Rock_Slate"
    },
    {
      "x": 4,
      "y": 30,
      "z": -12,
      "name": "Rock_Slate"
    },
    {
      "x": 4,
      "y": 31,
      "z": -12,
      "name": "Rock_Slate"
    },
    {
      "x": 4,
      "y": 32,
      "z": -12,
      "name": "Rock_Slate"
    },
    {
      "x": 4,
      "y": 7,
      "z": -7,
      "name": "Rock_Slate_Cobble"
    },
    {
      "x": 4,
      "y": 7,
      "z": -6,
      "name": "Rock_Slate_Cobble"
    },
    {
      "x": 4,
      "y": 7,
      "z": -5,
      "name": "Rock_Slate_Cobble"
    },
    {
      "x": 4,
      "y": 7,
      "z": -4,
      "name": "Rock_Slate_Cobble"
    },
    {
      "x": 4,
      "y": 7,
      "z": -3,
      "name": "Rock_Slate_Cobble"
    },
    {
      "x": 4,
      "y": 7,
      "z": -2,
      "name": "Rock_Slate_Cobble"
    },
    {
      "x": 4,
      "y": 6,
      "z": -1,
      "name": "Rock_Slate_Cobble"
    },
    {
      "x": 4,
      "y": 7,
      "z": -1,
      "name": "Rock_Slate_Cobble"
    },
    {
      "x": 4,
      "y": 7,
      "z": 0,
      "name": "Rock_Slate_Cobble"
    },
    {
      "x": 4,
      "y": 7,
      "z": 1,
      "name": "Rock_Slate_Cobble"
    },
    {
      "x": 4,
      "y": 7,
      "z": 2,
      "name": "Rock_Slate_Cobble"
    },
    {
      "x": 4,
      "y": 7,
      "z": 3,
      "name": "Rock_Slate_Cobble"
    },
    {
      "x": 4,
      "y": 7,
      "z": 4,
      "name": "Rock_Slate_Cobble"
    },
    {
      "x": 4,
      "y": 28,
      "z": 12,
      "name": "Rock_Slate"
    },
    {
      "x": 4,
      "y": 29,
      "z": 12,
      "name": "Rock_Slate"
    },
    {
      "x": 4,
      "y": 30,
      "z": 12,
      "name": "Rock_Slate"
    },
    {
      "x": 5,
      "y": 29,
      "z": -12,
      "name": "Rock_Slate"
    },
    {
      "x": 5,
      "y": 30,
      "z": -12,
      "name": "Rock_Slate"
    },
    {
      "x": 5,
      "y": 31,
      "z": -12,
      "name": "Rock_Slate"
    },
    {
      "x": 5,
      "y": 32,
      "z": -12,
      "name": "Rock_Slate"
    },
    {
      "x": 5,
      "y": 7,
      "z": -6,
      "name": "Rock_Slate_Cobble"
    },
    {
      "x": 5,
      "y": 7,
      "z": -5,
      "name": "Rock_Slate_Cobble"
    },
    {
      "x": 5,
      "y": 7,
      "z": -4,
      "name": "Rock_Slate_Cobble"
    },
    {
      "x": 5,
      "y": 7,
      "z": -3,
      "name": "Rock_Slate_Cobble"
    },
    {
      "x": 5,
      "y": 7,
      "z": -2,
      "name": "Rock_Slate_Cobble"
    },
    {
      "x": 5,
      "y": 7,
      "z": -1,
      "name": "Rock_Slate_Cobble"
    },
    {
      "x": 5,
      "y": 7,
      "z": 0,
      "name": "Rock_Slate_Cobble"
    },
    {
      "x": 5,
      "y": 7,
      "z": 1,
      "name": "Rock_Slate_Cobble"
    },
    {
      "x": 5,
      "y": 7,
      "z": 2,
      "name": "Rock_Slate_Cobble"
    },
    {
      "x": 5,
      "y": 7,
      "z": 3,
      "name": "Rock_Slate_Cobble"
    },
    {
      "x": 5,
      "y": 27,
      "z": 12,
      "name": "Rock_Slate"
    },
    {
      "x": 5,
      "y": 28,
      "z": 12,
      "name": "Rock_Slate"
    },
    {
      "x": 5,
      "y": 29,
      "z": 12,
      "name": "Rock_Slate"
    },
    {
      "x": 5,
      "y": 30,
      "z": 12,
      "name": "Rock_Slate"
    },
    {
      "x": 5,
      "y": 31,
      "z": 12,
      "name": "Rock_Slate"
    },
    {
      "x": 6,
      "y": 9,
      "z": -12,
      "name": "Rock_Slate"
    },
    {
      "x": 6,
      "y": 10,
      "z": -12,
      "name": "Rock_Slate"
    },
    {
      "x": 6,
      "y": 11,
      "z": -12,
      "name": "Rock_Slate"
    },
    {
      "x": 6,
      "y": 12,
      "z": -12,
      "name": "Rock_Slate"
    },
    {
      "x": 6,
      "y": 13,
      "z": -12,
      "name": "Rock_Slate"
    },
    {
      "x": 6,
      "y": 14,
      "z": -12,
      "name": "Rock_Slate"
    },
    {
      "x": 6,
      "y": 15,
      "z": -12,
      "name": "Rock_Slate"
    },
    {
      "x": 6,
      "y": 16,
      "z": -12,
      "name": "Rock_Slate"
    },
    {
      "x": 6,
      "y": 17,
      "z": -12,
      "name": "Rock_Slate"
    },
    {
      "x": 6,
      "y": 18,
      "z": -12,
      "name": "Rock_Slate"
    },
    {
      "x": 6,
      "y": 19,
      "z": -12,
      "name": "Rock_Slate"
    },
    {
      "x": 6,
      "y": 20,
      "z": -12,
      "name": "Rock_Slate"
    },
    {
      "x": 6,
      "y": 21,
      "z": -12,
      "name": "Rock_Slate"
    },
    {
      "x": 6,
      "y": 22,
      "z": -12,
      "name": "Rock_Slate"
    },
    {
      "x": 6,
      "y": 23,
      "z": -12,
      "name": "Rock_Slate"
    },
    {
      "x": 6,
      "y": 24,
      "z": -12,
      "name": "Rock_Slate"
    },
    {
      "x": 6,
      "y": 25,
      "z": -12,
      "name": "Rock_Slate"
    },
    {
      "x": 6,
      "y": 26,
      "z": -12,
      "name": "Rock_Slate"
    },
    {
      "x": 6,
      "y": 27,
      "z": -12,
      "name": "Rock_Slate"
    },
    {
      "x": 6,
      "y": 28,
      "z": -12,
      "name": "Rock_Slate"
    },
    {
      "x": 6,
      "y": 29,
      "z": -12,
      "name": "Rock_Slate"
    },
    {
      "x": 6,
      "y": 30,
      "z": -12,
      "name": "Rock_Slate"
    },
    {
      "x": 6,
      "y": 31,
      "z": -12,
      "name": "Rock_Slate"
    },
    {
      "x": 6,
      "y": 32,
      "z": -12,
      "name": "Rock_Slate"
    },
    {
      "x": 6,
      "y": 8,
      "z": 12,
      "name": "Rock_Slate"
    },
    {
      "x": 6,
      "y": 9,
      "z": 12,
      "name": "Rock_Slate"
    },
    {
      "x": 6,
      "y": 10,
      "z": 12,
      "name": "Rock_Slate"
    },
    {
      "x": 6,
      "y": 11,
      "z": 12,
      "name": "Rock_Slate"
    },
    {
      "x": 6,
      "y": 12,
      "z": 12,
      "name": "Rock_Slate"
    },
    {
      "x": 6,
      "y": 13,
      "z": 12,
      "name": "Rock_Slate"
    },
    {
      "x": 6,
      "y": 14,
      "z": 12,
      "name": "Rock_Slate"
    },
    {
      "x": 6,
      "y": 15,
      "z": 12,
      "name": "Rock_Slate"
    },
    {
      "x": 6,
      "y": 16,
      "z": 12,
      "name": "Rock_Slate"
    },
    {
      "x": 6,
      "y": 17,
      "z": 12,
      "name": "Rock_Slate"
    },
    {
      "x": 6,
      "y": 18,
      "z": 12,
      "name": "Rock_Slate"
    },
    {
      "x": 6,
      "y": 19,
      "z": 12,
      "name": "Rock_Slate"
    },
    {
      "x": 6,
      "y": 20,
      "z": 12,
      "name": "Rock_Slate"
    },
    {
      "x": 6,
      "y": 21,
      "z": 12,
      "name": "Rock_Slate"
    },
    {
      "x": 6,
      "y": 22,
      "z": 12,
      "name": "Rock_Slate"
    },
    {
      "x": 6,
      "y": 23,
      "z": 12,
      "name": "Rock_Slate"
    },
    {
      "x": 6,
      "y": 24,
      "z": 12,
      "name": "Rock_Slate"
    },
    {
      "x": 6,
      "y": 25,
      "z": 12,
      "name": "Rock_Slate"
    },
    {
      "x": 6,
      "y": 26,
      "z": 12,
      "name": "Rock_Slate"
    },
    {
      "x": 6,
      "y": 27,
      "z": 12,
      "name": "Rock_Slate"
    },
    {
      "x": 6,
      "y": 28,
      "z": 12,
      "name": "Rock_Slate"
    },
    {
      "x": 6,
      "y": 29,
      "z": 12,
      "name": "Rock_Slate"
    },
    {
      "x": 6,
      "y": 30,
      "z": 12,
      "name": "Rock_Slate"
    },
    {
      "x": 6,
      "y": 31,
      "z": 12,
      "name": "Rock_Slate"
    },
    {
      "x": 7,
      "y": 8,
      "z": -12,
      "name": "Rock_Slate"
    },
    {
      "x": 7,
      "y": 9,
      "z": -12,
      "name": "Rock_Slate"
    },
    {
      "x": 7,
      "y": 10,
      "z": -12,
      "name": "Rock_Slate"
    },
    {
      "x": 7,
      "y": 11,
      "z": -12,
      "name": "Rock_Slate"
    },
    {
      "x": 7,
      "y": 12,
      "z": -12,
      "name": "Rock_Slate"
    },
    {
      "x": 7,
      "y": 13,
      "z": -12,
      "name": "Rock_Slate"
    },
    {
      "x": 7,
      "y": 14,
      "z": -12,
      "name": "Rock_Slate"
    },
    {
      "x": 7,
      "y": 15,
      "z": -12,
      "name": "Rock_Slate"
    },
    {
      "x": 7,
      "y": 16,
      "z": -12,
      "name": "Rock_Slate"
    },
    {
      "x": 7,
      "y": 17,
      "z": -12,
      "name": "Rock_Slate"
    },
    {
      "x": 7,
      "y": 18,
      "z": -12,
      "name": "Rock_Slate"
    },
    {
      "x": 7,
      "y": 19,
      "z": -12,
      "name": "Rock_Slate"
    },
    {
      "x": 7,
      "y": 20,
      "z": -12,
      "name": "Rock_Slate"
    },
    {
      "x": 7,
      "y": 21,
      "z": -12,
      "name": "Rock_Slate"
    },
    {
      "x": 7,
      "y": 22,
      "z": -12,
      "name": "Rock_Slate"
    },
    {
      "x": 7,
      "y": 23,
      "z": -12,
      "name": "Rock_Slate"
    },
    {
      "x": 7,
      "y": 24,
      "z": -12,
      "name": "Rock_Slate"
    },
    {
      "x": 7,
      "y": 25,
      "z": -12,
      "name": "Rock_Slate"
    },
    {
      "x": 7,
      "y": 26,
      "z": -12,
      "name": "Rock_Slate"
    },
    {
      "x": 7,
      "y": 27,
      "z": -12,
      "name": "Rock_Slate"
    },
    {
      "x": 7,
      "y": 28,
      "z": -12,
      "name": "Rock_Slate"
    },
    {
      "x": 7,
      "y": 29,
      "z": -12,
      "name": "Rock_Slate"
    },
    {
      "x": 7,
      "y": 30,
      "z": -12,
      "name": "Rock_Slate"
    },
    {
      "x": 7,
      "y": 31,
      "z": -12,
      "name": "Rock_Slate"
    },
    {
      "x": 7,
      "y": 32,
      "z": -12,
      "name": "Rock_Slate"
    },
    {
      "x": 7,
      "y": 28,
      "z": 12,
      "name": "Rock_Slate"
    },
    {
      "x": 7,
      "y": 29,
      "z": 12,
      "name": "Rock_Slate"
    },
    {
      "x": 7,
      "y": 30,
      "z": 12,
      "name": "Rock_Slate"
    },
    {
      "x": 7,
      "y": 31,
      "z": 12,
      "name": "Rock_Slate"
    },
    {
      "x": 8,
      "y": 28,
      "z": -12,
      "name": "Rock_Slate"
    },
    {
      "x": 8,
      "y": 29,
      "z": -12,
      "name": "Rock_Slate"
    },
    {
      "x": 8,
      "y": 30,
      "z": -12,
      "name": "Rock_Slate"
    },
    {
      "x": 8,
      "y": 31,
      "z": -12,
      "name": "Rock_Slate"
    },
    {
      "x": 8,
      "y": 32,
      "z": -12,
      "name": "Rock_Slate"
    },
    {
      "x": 8,
      "y": 30,
      "z": -11,
      "name": "Ore_Server"
    },
    {
      "x": 8,
      "y": 29,
      "z": 12,
      "name": "Rock_Slate"
    },
    {
      "x": 8,
      "y": 30,
      "z": 12,
      "name": "Rock_Slate"
    },
    {
      "x": 8,
      "y": 31,
      "z": 12,
      "name": "Rock_Slate"
    },
    {
      "x": 8,
      "y": 32,
      "z": 12,
      "name": "Rock_Slate"
    },
    {
      "x": 9,
      "y": 30,
      "z": -12,
      "name": "Rock_Slate"
    },
    {
      "x": 9,
      "y": 31,
      "z": -12,
      "name": "Rock_Slate"
    },
    {
      "x": 9,
      "y": 31,
      "z": 11,
      "name": "Ore_Server"
    },
    {
      "x": 9,
      "y": 30,
      "z": 12,
      "name": "Rock_Slate"
    },
    {
      "x": 9,
      "y": 31,
      "z": 12,
      "name": "Rock_Slate"
    },
    {
      "x": 10,
      "y": 29,
      "z": -12,
      "name": "Rock_Slate"
    },
    {
      "x": 10,
      "y": 30,
      "z": -12,
      "name": "Rock_Slate"
    },
    {
      "x": 10,
      "y": 31,
      "z": -12,
      "name": "Rock_Slate"
    },
    {
      "x": 10,
      "y": 32,
      "z": -12,
      "name": "Rock_Slate"
    },
    {
      "x": 10,
      "y": 9,
      "z": 12,
      "name": "Rock_Slate"
    },
    {
      "x": 10,
      "y": 10,
      "z": 12,
      "name": "Rock_Slate"
    },
    {
      "x": 10,
      "y": 11,
      "z": 12,
      "name": "Rock_Slate"
    },
    {
      "x": 10,
      "y": 12,
      "z": 12,
      "name": "Rock_Slate"
    },
    {
      "x": 10,
      "y": 13,
      "z": 12,
      "name": "Rock_Slate"
    },
    {
      "x": 10,
      "y": 14,
      "z": 12,
      "name": "Rock_Slate"
    },
    {
      "x": 10,
      "y": 15,
      "z": 12,
      "name": "Rock_Slate"
    },
    {
      "x": 10,
      "y": 16,
      "z": 12,
      "name": "Rock_Slate"
    },
    {
      "x": 10,
      "y": 17,
      "z": 12,
      "name": "Rock_Slate"
    },
    {
      "x": 10,
      "y": 18,
      "z": 12,
      "name": "Rock_Slate"
    },
    {
      "x": 10,
      "y": 19,
      "z": 12,
      "name": "Rock_Slate"
    },
    {
      "x": 10,
      "y": 20,
      "z": 12,
      "name": "Rock_Slate"
    },
    {
      "x": 10,
      "y": 21,
      "z": 12,
      "name": "Rock_Slate"
    },
    {
      "x": 10,
      "y": 22,
      "z": 12,
      "name": "Rock_Slate"
    },
    {
      "x": 10,
      "y": 23,
      "z": 12,
      "name": "Rock_Slate"
    },
    {
      "x": 10,
      "y": 24,
      "z": 12,
      "name": "Rock_Slate"
    },
    {
      "x": 10,
      "y": 25,
      "z": 12,
      "name": "Rock_Slate"
    },
    {
      "x": 10,
      "y": 26,
      "z": 12,
      "name": "Rock_Slate"
    },
    {
      "x": 10,
      "y": 27,
      "z": 12,
      "name": "Rock_Slate"
    },
    {
      "x": 10,
      "y": 28,
      "z": 12,
      "name": "Rock_Slate"
    },
    {
      "x": 10,
      "y": 29,
      "z": 12,
      "name": "Rock_Slate"
    },
    {
      "x": 10,
      "y": 30,
      "z": 12,
      "name": "Rock_Slate"
    },
    {
      "x": 10,
      "y": 31,
      "z": 12,
      "name": "Rock_Slate"
    },
    {
      "x": 10,
      "y": 32,
      "z": 12,
      "name": "Rock_Slate"
    },
    {
      "x": 11,
      "y": 10,
      "z": -12,
      "name": "Rock_Slate"
    },
    {
      "x": 11,
      "y": 11,
      "z": -12,
      "name": "Rock_Slate"
    },
    {
      "x": 11,
      "y": 12,
      "z": -12,
      "name": "Rock_Slate"
    },
    {
      "x": 11,
      "y": 13,
      "z": -12,
      "name": "Rock_Slate"
    },
    {
      "x": 11,
      "y": 14,
      "z": -12,
      "name": "Rock_Slate"
    },
    {
      "x": 11,
      "y": 15,
      "z": -12,
      "name": "Rock_Slate"
    },
    {
      "x": 11,
      "y": 16,
      "z": -12,
      "name": "Rock_Slate"
    },
    {
      "x": 11,
      "y": 17,
      "z": -12,
      "name": "Rock_Slate"
    },
    {
      "x": 11,
      "y": 18,
      "z": -12,
      "name": "Rock_Slate"
    },
    {
      "x": 11,
      "y": 19,
      "z": -12,
      "name": "Rock_Slate"
    },
    {
      "x": 11,
      "y": 20,
      "z": -12,
      "name": "Rock_Slate"
    },
    {
      "x": 11,
      "y": 21,
      "z": -12,
      "name": "Rock_Slate"
    },
    {
      "x": 11,
      "y": 22,
      "z": -12,
      "name": "Rock_Slate"
    },
    {
      "x": 11,
      "y": 23,
      "z": -12,
      "name": "Rock_Slate"
    },
    {
      "x": 11,
      "y": 24,
      "z": -12,
      "name": "Rock_Slate"
    },
    {
      "x": 11,
      "y": 25,
      "z": -12,
      "name": "Rock_Slate"
    },
    {
      "x": 11,
      "y": 26,
      "z": -12,
      "name": "Rock_Slate"
    },
    {
      "x": 11,
      "y": 27,
      "z": -12,
      "name": "Rock_Slate"
    },
    {
      "x": 11,
      "y": 28,
      "z": -12,
      "name": "Rock_Slate"
    },
    {
      "x": 11,
      "y": 29,
      "z": -12,
      "name": "Rock_Slate"
    },
    {
      "x": 11,
      "y": 30,
      "z": -12,
      "name": "Rock_Slate"
    },
    {
      "x": 11,
      "y": 31,
      "z": -12,
      "name": "Rock_Slate"
    },
    {
      "x": 11,
      "y": 30,
      "z": -11,
      "name": "Ore_Server"
    },
    {
      "x": 11,
      "y": 31,
      "z": -10,
      "name": "Ore_Server"
    },
    {
      "x": 11,
      "y": 31,
      "z": -2,
      "name": "Ore_Server"
    },
    {
      "x": 11,
      "y": 31,
      "z": 1,
      "name": "Ore_Server"
    },
    {
      "x": 11,
      "y": 30,
      "z": 8,
      "name": "Ore_Server"
    },
    {
      "x": 11,
      "y": 29,
      "z": 11,
      "name": "Ore_Server"
    },
    {
      "x": 11,
      "y": 8,
      "z": 12,
      "name": "Rock_Slate"
    },
    {
      "x": 11,
      "y": 9,
      "z": 12,
      "name": "Rock_Slate"
    },
    {
      "x": 11,
      "y": 10,
      "z": 12,
      "name": "Rock_Slate"
    },
    {
      "x": 11,
      "y": 11,
      "z": 12,
      "name": "Rock_Slate"
    },
    {
      "x": 11,
      "y": 12,
      "z": 12,
      "name": "Rock_Slate"
    },
    {
      "x": 11,
      "y": 13,
      "z": 12,
      "name": "Rock_Slate"
    },
    {
      "x": 11,
      "y": 14,
      "z": 12,
      "name": "Rock_Slate"
    },
    {
      "x": 11,
      "y": 15,
      "z": 12,
      "name": "Rock_Slate"
    },
    {
      "x": 11,
      "y": 16,
      "z": 12,
      "name": "Rock_Slate"
    },
    {
      "x": 11,
      "y": 17,
      "z": 12,
      "name": "Rock_Slate"
    },
    {
      "x": 11,
      "y": 18,
      "z": 12,
      "name": "Rock_Slate"
    },
    {
      "x": 11,
      "y": 19,
      "z": 12,
      "name": "Rock_Slate"
    },
    {
      "x": 11,
      "y": 20,
      "z": 12,
      "name": "Rock_Slate"
    },
    {
      "x": 11,
      "y": 21,
      "z": 12,
      "name": "Rock_Slate"
    },
    {
      "x": 11,
      "y": 22,
      "z": 12,
      "name": "Rock_Slate"
    },
    {
      "x": 11,
      "y": 23,
      "z": 12,
      "name": "Rock_Slate"
    },
    {
      "x": 11,
      "y": 24,
      "z": 12,
      "name": "Rock_Slate"
    },
    {
      "x": 11,
      "y": 25,
      "z": 12,
      "name": "Rock_Slate"
    },
    {
      "x": 11,
      "y": 26,
      "z": 12,
      "name": "Rock_Slate"
    },
    {
      "x": 11,
      "y": 27,
      "z": 12,
      "name": "Rock_Slate"
    },
    {
      "x": 11,
      "y": 28,
      "z": 12,
      "name": "Rock_Slate"
    },
    {
      "x": 11,
      "y": 29,
      "z": 12,
      "name": "Rock_Slate"
    },
    {
      "x": 11,
      "y": 30,
      "z": 12,
      "name": "Rock_Slate"
    },
    {
      "x": 11,
      "y": 31,
      "z": 12,
      "name": "Rock_Slate"
    },
    {
      "x": 11,
      "y": 32,
      "z": 12,
      "name": "Rock_Slate"
    },
    {
      "x": 12,
      "y": 8,
      "z": -12,
      "name": "Rock_Slate"
    },
    {
      "x": 12,
      "y": 9,
      "z": -12,
      "name": "Rock_Slate"
    },
    {
      "x": 12,
      "y": 10,
      "z": -12,
      "name": "Rock_Slate"
    },
    {
      "x": 12,
      "y": 11,
      "z": -12,
      "name": "Rock_Slate"
    },
    {
      "x": 12,
      "y": 12,
      "z": -12,
      "name": "Rock_Slate"
    },
    {
      "x": 12,
      "y": 13,
      "z": -12,
      "name": "Rock_Slate"
    },
    {
      "x": 12,
      "y": 14,
      "z": -12,
      "name": "Rock_Slate"
    },
    {
      "x": 12,
      "y": 15,
      "z": -12,
      "name": "Rock_Slate"
    },
    {
      "x": 12,
      "y": 16,
      "z": -12,
      "name": "Rock_Slate"
    },
    {
      "x": 12,
      "y": 17,
      "z": -12,
      "name": "Rock_Slate"
    },
    {
      "x": 12,
      "y": 18,
      "z": -12,
      "name": "Rock_Slate"
    },
    {
      "x": 12,
      "y": 19,
      "z": -12,
      "name": "Rock_Slate"
    },
    {
      "x": 12,
      "y": 20,
      "z": -12,
      "name": "Rock_Slate"
    },
    {
      "x": 12,
      "y": 21,
      "z": -12,
      "name": "Rock_Slate"
    },
    {
      "x": 12,
      "y": 22,
      "z": -12,
      "name": "Rock_Slate"
    },
    {
      "x": 12,
      "y": 23,
      "z": -12,
      "name": "Rock_Slate"
    },
    {
      "x": 12,
      "y": 24,
      "z": -12,
      "name": "Rock_Slate"
    },
    {
      "x": 12,
      "y": 25,
      "z": -12,
      "name": "Rock_Slate"
    },
    {
      "x": 12,
      "y": 26,
      "z": -12,
      "name": "Rock_Slate"
    },
    {
      "x": 12,
      "y": 27,
      "z": -12,
      "name": "Rock_Slate"
    },
    {
      "x": 12,
      "y": 28,
      "z": -12,
      "name": "Rock_Slate"
    },
    {
      "x": 12,
      "y": 29,
      "z": -12,
      "name": "Rock_Slate"
    },
    {
      "x": 12,
      "y": 30,
      "z": -12,
      "name": "Rock_Slate"
    },
    {
      "x": 12,
      "y": 31,
      "z": -12,
      "name": "Rock_Slate"
    },
    {
      "x": 12,
      "y": 32,
      "z": -12,
      "name": "Rock_Slate"
    },
    {
      "x": 12,
      "y": 11,
      "z": -11,
      "name": "Rock_Slate"
    },
    {
      "x": 12,
      "y": 12,
      "z": -11,
      "name": "Rock_Slate"
    },
    {
      "x": 12,
      "y": 13,
      "z": -11,
      "name": "Rock_Slate"
    },
    {
      "x": 12,
      "y": 14,
      "z": -11,
      "name": "Rock_Slate"
    },
    {
      "x": 12,
      "y": 15,
      "z": -11,
      "name": "Rock_Slate"
    },
    {
      "x": 12,
      "y": 16,
      "z": -11,
      "name": "Rock_Slate"
    },
    {
      "x": 12,
      "y": 17,
      "z": -11,
      "name": "Rock_Slate"
    },
    {
      "x": 12,
      "y": 18,
      "z": -11,
      "name": "Rock_Slate"
    },
    {
      "x": 12,
      "y": 19,
      "z": -11,
      "name": "Rock_Slate"
    },
    {
      "x": 12,
      "y": 20,
      "z": -11,
      "name": "Rock_Slate"
    },
    {
      "x": 12,
      "y": 21,
      "z": -11,
      "name": "Rock_Slate"
    },
    {
      "x": 12,
      "y": 22,
      "z": -11,
      "name": "Rock_Slate"
    },
    {
      "x": 12,
      "y": 23,
      "z": -11,
      "name": "Rock_Slate"
    },
    {
      "x": 12,
      "y": 24,
      "z": -11,
      "name": "Rock_Slate"
    },
    {
      "x": 12,
      "y": 25,
      "z": -11,
      "name": "Rock_Slate"
    },
    {
      "x": 12,
      "y": 26,
      "z": -11,
      "name": "Rock_Slate"
    },
    {
      "x": 12,
      "y": 27,
      "z": -11,
      "name": "Rock_Slate"
    },
    {
      "x": 12,
      "y": 28,
      "z": -11,
      "name": "Rock_Slate"
    },
    {
      "x": 12,
      "y": 29,
      "z": -11,
      "name": "Rock_Slate"
    },
    {
      "x": 12,
      "y": 30,
      "z": -11,
      "name": "Rock_Slate"
    },
    {
      "x": 12,
      "y": 31,
      "z": -11,
      "name": "Rock_Slate"
    },
    {
      "x": 12,
      "y": 32,
      "z": -11,
      "name": "Rock_Slate"
    },
    {
      "x": 12,
      "y": 28,
      "z": -10,
      "name": "Rock_Slate"
    },
    {
      "x": 12,
      "y": 29,
      "z": -10,
      "name": "Rock_Slate"
    },
    {
      "x": 12,
      "y": 30,
      "z": -10,
      "name": "Rock_Slate"
    },
    {
      "x": 12,
      "y": 31,
      "z": -10,
      "name": "Rock_Slate"
    },
    {
      "x": 12,
      "y": 32,
      "z": -10,
      "name": "Rock_Slate"
    },
    {
      "x": 12,
      "y": 30,
      "z": -9,
      "name": "Rock_Slate"
    },
    {
      "x": 12,
      "y": 31,
      "z": -9,
      "name": "Rock_Slate"
    },
    {
      "x": 12,
      "y": 29,
      "z": -8,
      "name": "Rock_Slate"
    },
    {
      "x": 12,
      "y": 30,
      "z": -8,
      "name": "Rock_Slate"
    },
    {
      "x": 12,
      "y": 31,
      "z": -8,
      "name": "Rock_Slate"
    },
    {
      "x": 12,
      "y": 9,
      "z": -7,
      "name": "Rock_Slate"
    },
    {
      "x": 12,
      "y": 10,
      "z": -7,
      "name": "Rock_Slate"
    },
    {
      "x": 12,
      "y": 11,
      "z": -7,
      "name": "Rock_Slate"
    },
    {
      "x": 12,
      "y": 12,
      "z": -7,
      "name": "Rock_Slate"
    },
    {
      "x": 12,
      "y": 13,
      "z": -7,
      "name": "Rock_Slate"
    },
    {
      "x": 12,
      "y": 14,
      "z": -7,
      "name": "Rock_Slate"
    },
    {
      "x": 12,
      "y": 15,
      "z": -7,
      "name": "Rock_Slate"
    },
    {
      "x": 12,
      "y": 16,
      "z": -7,
      "name": "Rock_Slate"
    },
    {
      "x": 12,
      "y": 17,
      "z": -7,
      "name": "Rock_Slate"
    },
    {
      "x": 12,
      "y": 18,
      "z": -7,
      "name": "Rock_Slate"
    },
    {
      "x": 12,
      "y": 19,
      "z": -7,
      "name": "Rock_Slate"
    },
    {
      "x": 12,
      "y": 20,
      "z": -7,
      "name": "Rock_Slate"
    },
    {
      "x": 12,
      "y": 21,
      "z": -7,
      "name": "Rock_Slate"
    },
    {
      "x": 12,
      "y": 22,
      "z": -7,
      "name": "Rock_Slate"
    },
    {
      "x": 12,
      "y": 23,
      "z": -7,
      "name": "Rock_Slate"
    },
    {
      "x": 12,
      "y": 24,
      "z": -7,
      "name": "Rock_Slate"
    },
    {
      "x": 12,
      "y": 25,
      "z": -7,
      "name": "Rock_Slate"
    },
    {
      "x": 12,
      "y": 26,
      "z": -7,
      "name": "Rock_Slate"
    },
    {
      "x": 12,
      "y": 27,
      "z": -7,
      "name": "Rock_Slate"
    },
    {
      "x": 12,
      "y": 28,
      "z": -7,
      "name": "Rock_Slate"
    },
    {
      "x": 12,
      "y": 29,
      "z": -7,
      "name": "Rock_Slate"
    },
    {
      "x": 12,
      "y": 30,
      "z": -7,
      "name": "Rock_Slate"
    },
    {
      "x": 12,
      "y": 8,
      "z": -6,
      "name": "Rock_Slate"
    },
    {
      "x": 12,
      "y": 9,
      "z": -6,
      "name": "Rock_Slate"
    },
    {
      "x": 12,
      "y": 10,
      "z": -6,
      "name": "Rock_Slate"
    },
    {
      "x": 12,
      "y": 11,
      "z": -6,
      "name": "Rock_Slate"
    },
    {
      "x": 12,
      "y": 12,
      "z": -6,
      "name": "Rock_Slate"
    },
    {
      "x": 12,
      "y": 13,
      "z": -6,
      "name": "Rock_Slate"
    },
    {
      "x": 12,
      "y": 14,
      "z": -6,
      "name": "Rock_Slate"
    },
    {
      "x": 12,
      "y": 15,
      "z": -6,
      "name": "Rock_Slate"
    },
    {
      "x": 12,
      "y": 16,
      "z": -6,
      "name": "Rock_Slate"
    },
    {
      "x": 12,
      "y": 17,
      "z": -6,
      "name": "Rock_Slate"
    },
    {
      "x": 12,
      "y": 18,
      "z": -6,
      "name": "Rock_Slate"
    },
    {
      "x": 12,
      "y": 19,
      "z": -6,
      "name": "Rock_Slate"
    },
    {
      "x": 12,
      "y": 20,
      "z": -6,
      "name": "Rock_Slate"
    },
    {
      "x": 12,
      "y": 21,
      "z": -6,
      "name": "Rock_Slate"
    },
    {
      "x": 12,
      "y": 22,
      "z": -6,
      "name": "Rock_Slate"
    },
    {
      "x": 12,
      "y": 23,
      "z": -6,
      "name": "Rock_Slate"
    },
    {
      "x": 12,
      "y": 24,
      "z": -6,
      "name": "Rock_Slate"
    },
    {
      "x": 12,
      "y": 25,
      "z": -6,
      "name": "Rock_Slate"
    },
    {
      "x": 12,
      "y": 26,
      "z": -6,
      "name": "Rock_Slate"
    },
    {
      "x": 12,
      "y": 27,
      "z": -6,
      "name": "Rock_Slate"
    },
    {
      "x": 12,
      "y": 28,
      "z": -6,
      "name": "Rock_Slate"
    },
    {
      "x": 12,
      "y": 29,
      "z": -6,
      "name": "Rock_Slate"
    },
    {
      "x": 12,
      "y": 30,
      "z": -6,
      "name": "Rock_Slate"
    },
    {
      "x": 12,
      "y": 31,
      "z": -6,
      "name": "Rock_Slate"
    },
    {
      "x": 12,
      "y": 8,
      "z": -5,
      "name": "Rock_Slate"
    },
    {
      "x": 12,
      "y": 9,
      "z": -5,
      "name": "Rock_Slate"
    },
    {
      "x": 12,
      "y": 10,
      "z": -5,
      "name": "Rock_Slate"
    },
    {
      "x": 12,
      "y": 11,
      "z": -5,
      "name": "Rock_Slate"
    },
    {
      "x": 12,
      "y": 12,
      "z": -5,
      "name": "Rock_Slate"
    },
    {
      "x": 12,
      "y": 13,
      "z": -5,
      "name": "Rock_Slate"
    },
    {
      "x": 12,
      "y": 14,
      "z": -5,
      "name": "Rock_Slate"
    },
    {
      "x": 12,
      "y": 15,
      "z": -5,
      "name": "Rock_Slate"
    },
    {
      "x": 12,
      "y": 16,
      "z": -5,
      "name": "Rock_Slate"
    },
    {
      "x": 12,
      "y": 17,
      "z": -5,
      "name": "Rock_Slate"
    },
    {
      "x": 12,
      "y": 18,
      "z": -5,
      "name": "Rock_Slate"
    },
    {
      "x": 12,
      "y": 19,
      "z": -5,
      "name": "Rock_Slate"
    },
    {
      "x": 12,
      "y": 20,
      "z": -5,
      "name": "Rock_Slate"
    },
    {
      "x": 12,
      "y": 21,
      "z": -5,
      "name": "Rock_Slate"
    },
    {
      "x": 12,
      "y": 22,
      "z": -5,
      "name": "Rock_Slate"
    },
    {
      "x": 12,
      "y": 23,
      "z": -5,
      "name": "Rock_Slate"
    },
    {
      "x": 12,
      "y": 24,
      "z": -5,
      "name": "Rock_Slate"
    },
    {
      "x": 12,
      "y": 25,
      "z": -5,
      "name": "Rock_Slate"
    },
    {
      "x": 12,
      "y": 26,
      "z": -5,
      "name": "Rock_Slate"
    },
    {
      "x": 12,
      "y": 27,
      "z": -5,
      "name": "Rock_Slate"
    },
    {
      "x": 12,
      "y": 28,
      "z": -5,
      "name": "Rock_Slate"
    },
    {
      "x": 12,
      "y": 29,
      "z": -5,
      "name": "Rock_Slate"
    },
    {
      "x": 12,
      "y": 30,
      "z": -5,
      "name": "Rock_Slate"
    },
    {
      "x": 12,
      "y": 31,
      "z": -5,
      "name": "Rock_Slate"
    },
    {
      "x": 12,
      "y": 32,
      "z": -5,
      "name": "Rock_Slate"
    },
    {
      "x": 12,
      "y": 31,
      "z": -4,
      "name": "Rock_Slate"
    },
    {
      "x": 12,
      "y": 30,
      "z": -3,
      "name": "Rock_Slate"
    },
    {
      "x": 12,
      "y": 31,
      "z": -3,
      "name": "Rock_Slate"
    },
    {
      "x": 12,
      "y": 32,
      "z": -3,
      "name": "Rock_Slate"
    },
    {
      "x": 12,
      "y": 28,
      "z": -2,
      "name": "Rock_Slate"
    },
    {
      "x": 12,
      "y": 29,
      "z": -2,
      "name": "Rock_Slate"
    },
    {
      "x": 12,
      "y": 30,
      "z": -2,
      "name": "Rock_Slate"
    },
    {
      "x": 12,
      "y": 31,
      "z": -2,
      "name": "Rock_Slate"
    },
    {
      "x": 12,
      "y": 8,
      "z": -1,
      "name": "Rock_Slate"
    },
    {
      "x": 12,
      "y": 9,
      "z": -1,
      "name": "Rock_Slate"
    },
    {
      "x": 12,
      "y": 10,
      "z": -1,
      "name": "Rock_Slate"
    },
    {
      "x": 12,
      "y": 11,
      "z": -1,
      "name": "Rock_Slate"
    },
    {
      "x": 12,
      "y": 12,
      "z": -1,
      "name": "Rock_Slate"
    },
    {
      "x": 12,
      "y": 13,
      "z": -1,
      "name": "Rock_Slate"
    },
    {
      "x": 12,
      "y": 14,
      "z": -1,
      "name": "Rock_Slate"
    },
    {
      "x": 12,
      "y": 15,
      "z": -1,
      "name": "Rock_Slate"
    },
    {
      "x": 12,
      "y": 16,
      "z": -1,
      "name": "Rock_Slate"
    },
    {
      "x": 12,
      "y": 17,
      "z": -1,
      "name": "Rock_Slate"
    },
    {
      "x": 12,
      "y": 18,
      "z": -1,
      "name": "Rock_Slate"
    },
    {
      "x": 12,
      "y": 19,
      "z": -1,
      "name": "Rock_Slate"
    },
    {
      "x": 12,
      "y": 20,
      "z": -1,
      "name": "Rock_Slate"
    },
    {
      "x": 12,
      "y": 21,
      "z": -1,
      "name": "Rock_Slate"
    },
    {
      "x": 12,
      "y": 22,
      "z": -1,
      "name": "Rock_Slate"
    },
    {
      "x": 12,
      "y": 23,
      "z": -1,
      "name": "Rock_Slate"
    },
    {
      "x": 12,
      "y": 24,
      "z": -1,
      "name": "Rock_Slate"
    },
    {
      "x": 12,
      "y": 25,
      "z": -1,
      "name": "Rock_Slate"
    },
    {
      "x": 12,
      "y": 26,
      "z": -1,
      "name": "Rock_Slate"
    },
    {
      "x": 12,
      "y": 27,
      "z": -1,
      "name": "Rock_Slate"
    },
    {
      "x": 12,
      "y": 28,
      "z": -1,
      "name": "Rock_Slate"
    },
    {
      "x": 12,
      "y": 29,
      "z": -1,
      "name": "Rock_Slate"
    },
    {
      "x": 12,
      "y": 30,
      "z": -1,
      "name": "Rock_Slate"
    },
    {
      "x": 12,
      "y": 31,
      "z": -1,
      "name": "Rock_Slate"
    },
    {
      "x": 12,
      "y": 32,
      "z": -1,
      "name": "Rock_Slate"
    },
    {
      "x": 12,
      "y": 9,
      "z": 0,
      "name": "Rock_Slate"
    },
    {
      "x": 12,
      "y": 10,
      "z": 0,
      "name": "Rock_Slate"
    },
    {
      "x": 12,
      "y": 11,
      "z": 0,
      "name": "Rock_Slate"
    },
    {
      "x": 12,
      "y": 12,
      "z": 0,
      "name": "Rock_Slate"
    },
    {
      "x": 12,
      "y": 13,
      "z": 0,
      "name": "Rock_Slate"
    },
    {
      "x": 12,
      "y": 14,
      "z": 0,
      "name": "Rock_Slate"
    },
    {
      "x": 12,
      "y": 15,
      "z": 0,
      "name": "Rock_Slate"
    },
    {
      "x": 12,
      "y": 16,
      "z": 0,
      "name": "Rock_Slate"
    },
    {
      "x": 12,
      "y": 17,
      "z": 0,
      "name": "Rock_Slate"
    },
    {
      "x": 12,
      "y": 18,
      "z": 0,
      "name": "Rock_Slate"
    },
    {
      "x": 12,
      "y": 19,
      "z": 0,
      "name": "Rock_Slate"
    },
    {
      "x": 12,
      "y": 20,
      "z": 0,
      "name": "Rock_Slate"
    },
    {
      "x": 12,
      "y": 21,
      "z": 0,
      "name": "Rock_Slate"
    },
    {
      "x": 12,
      "y": 22,
      "z": 0,
      "name": "Rock_Slate"
    },
    {
      "x": 12,
      "y": 23,
      "z": 0,
      "name": "Rock_Slate"
    },
    {
      "x": 12,
      "y": 24,
      "z": 0,
      "name": "Rock_Slate"
    },
    {
      "x": 12,
      "y": 25,
      "z": 0,
      "name": "Rock_Slate"
    },
    {
      "x": 12,
      "y": 26,
      "z": 0,
      "name": "Rock_Slate"
    },
    {
      "x": 12,
      "y": 27,
      "z": 0,
      "name": "Rock_Slate"
    },
    {
